Workbook

Sheet Info
D1: დანართი 1
B2: მზღვეველის ფინანსური ანგარიშგების ფორმები
B4: ზოგადი ინფორმაცია მზღვეველის შესახებ
B6: 1 | C6: მზღვეველის სრული დასახელება
B7: 2 | C7: საანგარიშო პერიოდი
B8: 3 | C8: ორგანიზაციის სამეთვალყურეო საბჭოს თავმჯდომარე
B9: 4 | C9: ორგანიზაციის გენერალური დირექტორი (დირექტორი)
B10: 5 | C10: ორგანიზაციის მთავარი ბუღალტერი
B11: 6 | C11: ორგანიზაციის მისამართი
B12: 7 | C12: ორგანიზაციის ტელეფონი
B13: 8 | C13: ორგანიზაციის ფაქსი
B14: 9 | C14: ორგანიზაციის ელექტრონული ფოსტის მისამართი
B15: 10 | C15: ორგანიზაციის ვებ - გვერდი
B16: 11 | C16: ორგანიზაციის ფილიალების რაოდენობა
B17: 12 | C17: ორგანიზაციის თანამშრომელთა რაოდენობა | D17: =SUM(D18:D20) -> 0
B18: 12.1 | C18: სათავოს მიხედვით
B19: 12.2 | C19: ფილიალების მიხედვით
B20: 12.3 | C20: სხვა თანამშრომლები
B21: 13 | C21: ორგანიზაციის გასული წლის გარე აუდიტორი
B22: 14 | C22: ანგარიშგებაზე პასუხისმგებელი პირი
B23: 15 | C23: ანგარიშგებაზე პასუხისმგებელი პირის ტელეფონის ნომერი
B24: 16 | C24: ანგარიშგებაზე პასუხისმგებელი პირის ელექტრონული ფოსტა

Sheet BS
B1: მზღვეველი: | E1: ფორმა N1
B2: ანგარიშგების თარიღი:
C4: ფინანსური მდგომარეობის ანგარიშგება (საბალანსო უწყისი)
E5: ლარებში
B6: სტრიქონის კოდი | C6: N | E6: საანგარიშო პერიოდი | F6: გასული წლის შესაბამისი პერიოდი
C8: აქტივები
B9: 00010 | C9: 1 | D9: - ფულადი სახსრები და მათი ექვივალენტები | E9: ='BS-C'!E27 -> 0 | F9: ='BS-C'!F27 -> 0
B10: 00020 | C10: 2 | D10: - მოთხოვნები საკრედიტო დაწესებულებების მიმართ | E10: ='BS-D'!E1034 -> 0 | F10: ='BS-D'!F1034 -> 0
B11: 00030 | C11: 3 | D11: - გასაყიდად არსებული ფინანსური აქტივები | E11: ='BS-FA '!E93 -> 0 | F11: ='BS-FA '!F93 -> 0
B12: 00040 | C12: 4 | D12: - დაფარვის ვადამდე მფლობელობაში არსებული ფინანსური აქტივები | E12: ='BS-FA '!E436 -> 0 | F12: ='BS-FA '!F436 -> 0
B13: 00050 | C13: 5 | D13: - რეალური ღირებულებით აღრიცხული ფინანსური აქტივები, მოგებაში ან ზარალში ასახვით | E13: ='BS-FA '!E779 -> 0 | F13: ='BS-FA '!F779 -> 0
B14: 00060 | C14: 6 | D14: - სადაზღვევო მოთხოვნები, წმინდა | E14: ='BS-IR & RR'!E19 -> 0 | F14: ='BS-IR & RR'!F19 -> 0
B15: 00070 | C15: 7 | D15: - გადაზღვევის მოთხოვნები, წმინდა | E15: ='BS-IR & RR'!E35 -> 0 | F15: ='BS-IR & RR'!F35 -> 0
B16: 00080 | C16: 8 | D16: - მოთხოვნები გადარჩენილი ქონებიდან
B17: 00090 | C17: 9 | D17: - გაცემული სესხები, წმინდა | E17: ='BS-L'!K722 -> 0 | F17: ='BS-L'!R722 -> 0
B18: 00100 | C18: 10 | D18: - ინვესტიციები მეკავშირე კომპანიებში | E18: ='BS-I'!E476 -> 0 | F18: ='BS-I'!F476 -> 0
B19: 00110 | C19: 11 | D19: - ინვესტიციები შვილობილ კომპანიებში | E19: ='BS-I'!E946 -> 0 | F19: ='BS-I'!F946 -> 0
B20: 00120 | C20: 12 | D20: - გადამზღვევლის წილი სადაზღვევო რეზერვებში | E20: ='BS-R'!E18+'BS-R'!E38 -> 0 | F20: ='BS-R'!F18+'BS-R'!F38 -> 0
B21: 00130 | C21: 13 | D21: - გადავადებული საკომისიო ხარჯი | E21: ='BS-DC'!E13+'BS-DC'!E24 -> 0 | F21: ='BS-DC'!F13+'BS-DC'!F24 -> 0
B22: 00140 | C22: 14 | D22: - ძირითადი საშუალებები, წმინდა | E22: ='BS-PPE'!L18 -> 0
B23: 00150 | C23: 15 | D23: - საინვესტიციო ქონება | E23: ='BS-IP & OA'!E73 -> 0 | F23: ='BS-IP & OA'!F73 -> 0
B24: 00160 | C24: 16 | D24: - გუდვილი და სხვა არამატერიალური აქტივები, წმინდა | E24: ='BS-IA'!I19 -> 0
B25: 00170 | C25: 17 | D25: - გადავადებული საგადასახადო აქტივი
B26: 00180 | C26: 18 | D26: - სხვა აქტივები | E26: ='BS-IP & OA'!E92 -> 0 | F26: ='BS-IP & OA'!F92 -> 0
B27: 00190 | C27: 19 | D27: სულ აქტივები: | E27: =SUM(E9:E26) -> 0 | F27: =SUM(F9:F26) -> 0
C29: ვალდებულებები
B30: 00200 | C30: 20 | D30: - სადაზღვევო რეზერვები, ბრუტო | E30: ='BS-R'!E13+'BS-R'!E32 -> 0 | F30: ='BS-R'!F13+'BS-R'!F32 -> 0
B31: 00210 | C31: 21 | D31: - სხვა სადაზღვევო ვალდებულებები | E31: ='BS-OIL & OL'!E15 -> 0 | F31: ='BS-OIL & OL'!F15 -> 0
B32: 00220 | C32: 22 | D32: - ვალდებულებები რეგრესიდან და გადარჩენილი ქონებიდან
B33: 00230 | C33: 23 | D33: - ფინანსური ვალდებულებები | E33: ='BS-FL'!I286 -> 0 | F33: ='BS-FL'!N286 -> 0
B34: 00240 | C34: 24 | D34: - საპენსიო ვალდებულებები | E34: ='BS-PL'!E22+'BS-PL'!E27 -> 0 | F34: ='BS-PL'!F22+'BS-PL'!F27 -> 0
B35: 00250 | C35: 25 | D35: - ვალდებულებები მეკავშირე კომპანიებთან | E35: ='BS-LA'!E328 -> 0 | F35: ='BS-LA'!F328 -> 0
B36: 00260 | C36: 26 | D36: - ვალდებულებები შვილობილ კომპანიებთან | E36: ='BS-LA'!E650 -> 0 | F36: ='BS-LA'!F650 -> 0
B37: 00270 | C37: 27 | D37: - გადავადებული საკომისიო შემოსავალი | E37: ='BS-DC'!E17+'BS-DC'!E28 -> 0 | F37: ='BS-DC'!F17+'BS-DC'!F28 -> 0
B38: 00280 | C38: 28 | D38: - გადავადებული საგადასახადო ვალდებულება
B39: 00290 | C39: 29 | D39: - სხვა ვალდებულებები | E39: ='BS-OIL & OL'!E30 -> 0 | F39: ='BS-OIL & OL'!F30 -> 0
B40: 00300 | C40: 30 | D40: სულ ვალდებულებები: | E40: =SUM(E30:E39) -> 0 | F40: =SUM(F30:F39) -> 0
C42: კაპიტალი
B43: 00310 | C43: 31 | D43: - სააქციო კაპიტალი/კაპიტალი შპს-ში
B44: 00320 | C44: 32 | D44: - საემისიო კაპიტალი
...

Sheet BS-C
B1: მზღვეველი: | E1: ფორმა N1-1
B2: ანგარიშგების თარიღი:
D4: ფულადი სახსრები და მათი ექვივალენტები
F5: ლარებში
B6: სტრიქონის კოდი | C6: N | E6: საანგარიშო პერიოდი | F6: გასული წლის შესაბამისი პერიოდი
C8: ფულადი სახსრები და მათი ექვივალენტები (სახეობების მიხედვით)
B9: 00010 | C9: 1 | D9: ნაღდი ფული სალაროში | E9: =E31+E330+E629+E928 -> 0 | F9: =F31+F330+F629+F928 -> 0
B10: 00020 | C10: 2 | D10: ფული ბანკებში (მიმდინარე ანგარიშებზე) | E10: =E11+E12+E13+E14 -> 0 | F10: =F11+F12+F13+F14 -> 0
B11: 00030 | C11: 2.1 | D11: მიმდინარე ანგარიშებზე, რეზიდენტ ბანკებში | E11: =E33+E332+E631+E930 -> 0 | F11: =F33+F332+F631+F930 -> 0
B12: 00040 | C12: 2.2 | D12: მიმდინარე ანგარიშებზე დარიცხული %, რეზიდენტ ბანკებში | E12: =E54+E353+E652+E951 -> 0 | F12: =F54+F353+F652+F951 -> 0
B13: 00050 | C13: 2.3 | D13: მიმდინარე ანგარიშებზე, არარეზიდენტ ბანკებში | E13: =E75+E374+E673+E972 -> 0 | F13: =F75+F374+F673+F972 -> 0
B14: 00060 | C14: 2.4 | D14: მიმდინარე ანგარიშებზე დარიცხული %, არარეზიდენტ ბანკებში | E14: =E96+E395+E694+E993 -> 0 | F14: =F96+F395+F694+F993 -> 0
B15: 00070 | C15: 3 | D15: საბანკო დეპოზიტები (მოთხოვნამდე) | E15: =E16+E17+E18+E19 -> 0 | F15: =F16+F17+F18+F19 -> 0
B16: 00080 | C16: 3.1 | D16: საბანკო დეპოზიტები (მოთხოვნამდე), რეზიდენტ ბანკებში | E16: =E118+E417+E716+E1015 -> 0 | F16: =F118+F417+F716+F1015 -> 0
B17: 00090 | C17: 3.2 | D17: საბანკო დეპოზიტებზე (მოთხოვნამდე) დარიცხული %, რეზიდენტ ბანკებში | E17: =E139+E438+E737+E1036 -> 0 | F17: =F139+F438+F737+F1036 -> 0
B18: 00100 | C18: 3.3 | D18: საბანკო დეპოზიტები (მოთხოვნამდე), არარეზიდენტ ბანკებში | E18: =E160+E459+E758+E1057 -> 0 | F18: =F160+F459+F758+F1057 -> 0
B19: 00110 | C19: 3.4 | D19: საბანკო დეპოზიტებზე (მოთხოვნამდე) დარიცხული %, არარეზიდენტ ბანკებში | E19: =E181+E480+E779+E1078 -> 0 | F19: =F181+F480+F779+F1078 -> 0
B20: 00120 | C20: 4 | D20: მოკლევადიანი საბანკო დეპოზიტები (90 დღეზე ნაკლები ვადით) | E20: =E21+E22+E23+E24 -> 0 | F20: =F21+F22+F23+F24 -> 0
B21: 00130 | C21: 4.1 | D21: მოკლევადიანი საბანკო დეპოზიტები, რეზიდენტ ბანკებში | E21: =E203+E502+E801+E1100 -> 0 | F21: =F203+F502+F801+F1100 -> 0
B22: 00140 | C22: 4.2 | D22: მოკლევადიან საბანკო დეპოზიტებზე დარიცხული %, რეზიდენტ ბანკებში | E22: =E224+E523+E822+E1121 -> 0 | F22: =F224+F523+F822+F1121 -> 0
B23: 00150 | C23: 4.3 | D23: მოკლევადიანი საბანკო დეპოზიტები, არარეზიდენტ ბანკებში | E23: =E245+E544+E843+E1142 -> 0 | F23: =F245+F544+F843+F1142 -> 0
B24: 00160 | C24: 4.4 | D24: მოკლევადიან საბანკო დეპოზიტებზე დარიცხული %, არარეზიდენტ ბანკებში | E24: =E266+E565+E864+E1163 -> 0 | F24: =F266+F565+F864+F1163 -> 0
B25: 00170 | C25: 5 | D25: მოკლევადიანი ინვესტიციები (90 დღეზე ნაკლები ვადით) | E25: =E287+E586+E885+E1184 -> 0 | F25: =F287+F586+F885+F1184 -> 0
B26: 00180 | C26: 6 | D26: სხვა ფულადი სახსრები და მათი ექვივალენტები | E26: =E308+E607+E906+E1205 -> 0 | F26: =F308+F607+F906+F1205 -> 0
B27: 00190 | C27: სულ ფულადი სახსრები და მათი ექვივალენტები: (1+2+3+4+5+6) | E27: =E9+E10+E15+E20+E25+E26 -> 0 | F27: =F9+F10+F15+F20+F25+F26 -> 0
C29: ფულადი სახსრები და მათი ექვივალენტები (ვალუტაში კონცენტრირებული)
B30: 00200 | C30: 7 | D30: ლარი | E30: =E31+E32+E117+E202+E287+E308 -> 0 | F30: =F31+F32+F117+F202+F287+F308 -> 0
B31: 00210 | C31: 7.1 | D31: ნაღდი ფული სალაროში
B32: 00220 | C32: 7.2 | D32: ფული ბანკებში (მიმდინარე ანგარიშებზე) | E32: =E33+E54+E75+E96 -> 0 | F32: =F33+F54+F75+F96 -> 0
B33: 00230 | C33: 7.2.1 | D33: მიმდინარე ანგარიშებზე, რეზიდენტ ბანკებში | E33: =SUM(E34:E53) -> 0 | F33: =SUM(F34:F53) -> 0
B34: 00240 | C34: 7.2.1.1 | D34: ბანკის დასახელება, ბანკის რეგისტრაციის ქვეყანა
B35: 00250 | C35: 7.2.1.2 | D35: ბანკის დასახელება, ბანკის რეგისტრაციის ქვეყანა
B36: 00260 | C36: 7.2.1.3 | D36: ბანკის დასახელება, ბანკის რეგისტრაციის ქვეყანა
B37: 00270 | C37: 7.2.1.4 | D37: ბანკის დასახელება, ბანკის რეგისტრაციის ქვეყანა
B38: 00280 | C38: 7.2.1.5 | D38: ბანკის დასახელება, ბანკის რეგისტრაციის ქვეყანა
B39: 00290 | C39: 7.2.1.6 | D39: ბანკის დასახელება, ბანკის რეგისტრაციის ქვეყანა
B40: 00300 | C40: 7.2.1.7 | D40: ბანკის დასახელება, ბანკის რეგისტრაციის ქვეყანა
B41: 00310 | C41: 7.2.1.8 | D41: ბანკის დასახელება, ბანკის რეგისტრაციის ქვეყანა
B42: 00320 | C42: 7.2.1.9 | D42: ბანკის დასახელება, ბანკის რეგისტრაციის ქვეყანა
B43: 00330 | C43: 7.2.1.10 | D43: ბანკის დასახელება, ბანკის რეგისტრაციის ქვეყანა
...

Sheet BS-D
B1: მზღვეველი: | E1: ფორმა N1-2
B2: ანგარიშგების თარიღი:
D4: მოთხოვნები საკრედიტო დაწესებულებების მიმართ
E5: ლარებში
B6: სტრიქონის კოდი | C6: N | D6: ვადიანი დეპოზიტები ბანკებში | E6: საანგარიშო პერიოდი | F6: გასული წლის შესაბამისი პერიოდი
B8: 00010 | C8: 1 | D8: - მოკლევადიანი (365 და 365 დღეზე ნაკლები) (2+3+4+5) | E8: =E9+E94+E179+E264 -> 0 | F8: =F9+F94+F179+F264 -> 0
B9: 00020 | C9: 2 | D9: ლარი | E9: =E10+E31+E52+E73 -> 0 | F9: =F10+F31+F52+F73 -> 0
B10: 00030 | C10: 2.1 | D10: ვადიანი დეპოზიტები რეზიდენტ ბანკებში | E10: =SUM(E11:E30) -> 0 | F10: =SUM(F11:F30) -> 0
B11: 00040 | C11: 2.1.1 | D11: ბანკის დასახელება, ბანკის რეგისტრაციის ქვეყანა
B12: 00050 | C12: 2.1.2 | D12: ბანკის დასახელება, ბანკის რეგისტრაციის ქვეყანა
B13: 00060 | C13: 2.1.3 | D13: ბანკის დასახელება, ბანკის რეგისტრაციის ქვეყანა
B14: 00070 | C14: 2.1.4 | D14: ბანკის დასახელება, ბანკის რეგისტრაციის ქვეყანა
B15: 00080 | C15: 2.1.5 | D15: ბანკის დასახელება, ბანკის რეგისტრაციის ქვეყანა
B16: 00090 | C16: 2.1.6 | D16: ბანკის დასახელება, ბანკის რეგისტრაციის ქვეყანა
B17: 00100 | C17: 2.1.7 | D17: ბანკის დასახელება, ბანკის რეგისტრაციის ქვეყანა
B18: 00110 | C18: 2.1.8 | D18: ბანკის დასახელება, ბანკის რეგისტრაციის ქვეყანა
B19: 00120 | C19: 2.1.9 | D19: ბანკის დასახელება, ბანკის რეგისტრაციის ქვეყანა
B20: 00130 | C20: 2.1.10 | D20: ბანკის დასახელება, ბანკის რეგისტრაციის ქვეყანა
B21: 00140 | C21: 2.1.11 | D21: ბანკის დასახელება, ბანკის რეგისტრაციის ქვეყანა
B22: 00150 | C22: 2.1.12 | D22: ბანკის დასახელება, ბანკის რეგისტრაციის ქვეყანა
... B30: 00230 | C30: 2.1.20 | D30: ბანკის დასახელება, ბანკის რეგისტრაციის ქვეყანა
B31: 00240 | C31: 2.2 | D31: ვადიან დეპოზიტებზე დარიცხული %, რეზიდენტ ბანკებში | E31: =SUM(E32:E51) -> 0 | F31: =SUM(F32:F51) -> 0
B32: 00250 | C32: 2.2.1 | D32: ბანკის დასახელება, ბანკის რეგისტრაციის ქვეყანა
B33: 00260 | C33: 2.2.2 | D33: ბანკის დასახელება, ბანკის რეგისტრაციის ქვეყანა
B34: 00270 | C34: 2.2.3 | D34: ბანკის დასახელება, ბანკის რეგისტრაციის ქვეყანა
B35: 00280 | C35: 2.2.4 | D35: ბანკის დასახელება, ბანკის რეგისტრაციის ქვეყანა
B36: 00290 | C36: 2.2.5 | D36: ბანკის დასახელება, ბანკის რეგისტრაციის ქვეყანა
B37: 00300 | C37: 2.2.6 | D37: ბანკის დასახელება, ბანკის რეგისტრაციის ქვეყანა
B38: 00310 | C38: 2.2.7 | D38: ბანკის დასახელება, ბანკის რეგისტრაციის ქვეყანა
B39: 00320 | C39: 2.2.8 | D39: ბანკის დასახელება, ბანკის რეგისტრაციის ქვეყანა
B40: 00330 | C40: 2.2.9 | D40: ბანკის დასახელება, ბანკის რეგისტრაციის ქვეყანა
B41: 00340 | C41: 2.2.10 | D41: ბანკის დასახელება, ბანკის რეგისტრაციის ქვეყანა
B42: 00350 | C42: 2.2.11 | D42: ბანკის დასახელება, ბანკის რეგისტრაციის ქვეყანა
B43: 00360 | C43: 2.2.12 | D43: ბანკის დასახელება, ბანკის რეგისტრაციის ქვეყანა
... B51: 00440 | C51: 2.2.20 | D51: ბანკის დასახელება, ბანკის რეგისტრაციის ქვეყანა
B52: 00450 | C52: 2.3 | D52: ვადიანი დეპოზიტები არარეზიდენტ ბანკებში | E52: =SUM(E53:E72) -> 0 | F52: =SUM(F53:F72) -> 0
B53: 00460 | C53: 2.3.1 | D53: ბანკის დასახელება, ბანკის რეგისტრაციის ქვეყანა
B54: 00470 | C54: 2.3.2 | D54: ბანკის დასახელება, ბანკის რეგისტრაციის ქვეყანა
B55: 00480 | C55: 2.3.3 | D55: ბანკის დასახელება, ბანკის რეგისტრაციის ქვეყანა
B56: 00490 | C56: 2.3.4 | D56: ბანკის დასახელება, ბანკის რეგისტრაციის ქვეყანა
...

Sheet BS-FA 
B1: მზღვეველი: | E1: ფორმა N1-3
B2: ანგარიშგების თარიღი:
C4: ფინანსური აქტივები
E5: ლარებში
B6: სტრიქონის კოდი | C6: N | E6: საანგარიშო პერიოდი | F6: გასული წლის შესაბამისი პერიოდი
C8: გასაყიდად არსებული ფინანსური აქტივები
B9: 00010 | C9: 1 | D9: წილობრივი ინსტრუმენტები | E9: =SUM(E10:E29) -> 0 | F9: =SUM(F10:F29) -> 0
B10: 00020 | C10: 1.1 | D10: წილობრივი ინსტრუმენტის დასახელება, ემიტენტი, რეგისტრაციის ქვეყანა
B11: 00030 | C11: 1.2 | D11: წილობრივი ინსტრუმენტის დასახელება, ემიტენტი, რეგისტრაციის ქვეყანა
B12: 00040 | C12: 1.3 | D12: წილობრივი ინსტრუმენტის დასახელება, ემიტენტი, რეგისტრაციის ქვეყანა
B13: 00050 | C13: 1.4 | D13: წილობრივი ინსტრუმენტის დასახელება, ემიტენტი, რეგისტრაციის ქვეყანა
B14: 00060 | C14: 1.5 | D14: წილობრივი ინსტრუმენტის დასახელება, ემიტენტი, რეგისტრაციის ქვეყანა
B15: 00070 | C15: 1.6 | D15: წილობრივი ინსტრუმენტის დასახელება, ემიტენტი, რეგისტრაციის ქვეყანა
B16: 00080 | C16: 1.7 | D16: წილობრივი ინსტრუმენტის დასახელება, ემიტენტი, რეგისტრაციის ქვეყანა
B17: 00090 | C17: 1.8 | D17: წილობრივი ინსტრუმენტის დასახელება, ემიტენტი, რეგისტრაციის ქვეყანა
B18: 00100 | C18: 1.9 | D18: წილობრივი ინსტრუმენტის დასახელება, ემიტენტი, რეგისტრაციის ქვეყანა
B19: 00110 | C19: 1.1 | D19: წილობრივი ინსტრუმენტის დასახელება, ემიტენტი, რეგისტრაციის ქვეყანა
B20: 00120 | C20: 1.11 | D20: წილობრივი ინსტრუმენტის დასახელება, ემიტენტი, რეგისტრაციის ქვეყანა
B21: 00130 | C21: 1.12 | D21: წილობრივი ინსტრუმენტის დასახელება, ემიტენტი, რეგისტრაციის ქვეყანა
... B28: 00200 | C28: 1.19 | D28: წილობრივი ინსტრუმენტის დასახელება, ემიტენტი, რეგისტრაციის ქვეყანა
B29: 00210 | C29: 1.20 | D29: წილობრივი ინსტრუმენტის დასახელება, ემიტენტი, რეგისტრაციის ქვეყანა
B30: 00220 | C30: 2 | D30: სახელმწიფო სასესხო ფასიანი ქაღალდები | E30: =SUM(E31:E50) -> 0 | F30: =SUM(F31:F50) -> 0
B31: 00230 | C31: 2.1 | D31: სასესხო ფასიანი ქაღალდის დასახელება, ემიტენტი, რეგისტრაციის ქვეყანა
B32: 00240 | C32: 2.2 | D32: სასესხო ფასიანი ქაღალდის დასახელება, ემიტენტი, რეგისტრაციის ქვეყანა
B33: 00250 | C33: 2.3 | D33: სასესხო ფასიანი ქაღალდის დასახელება, ემიტენტი, რეგისტრაციის ქვეყანა
B34: 00260 | C34: 2.4 | D34: სასესხო ფასიანი ქაღალდის დასახელება, ემიტენტი, რეგისტრაციის ქვეყანა
B35: 00270 | C35: 2.5 | D35: სასესხო ფასიანი ქაღალდის დასახელება, ემიტენტი, რეგისტრაციის ქვეყანა
B36: 00280 | C36: 2.6 | D36: სასესხო ფასიანი ქაღალდის დასახელება, ემიტენტი, რეგისტრაციის ქვეყანა
B37: 00290 | C37: 2.7 | D37: სასესხო ფასიანი ქაღალდის დასახელება, ემიტენტი, რეგისტრაციის ქვეყანა
B38: 00300 | C38: 2.8 | D38: სასესხო ფასიანი ქაღალდის დასახელება, ემიტენტი, რეგისტრაციის ქვეყანა
B39: 00310 | C39: 2.9 | D39: სასესხო ფასიანი ქაღალდის დასახელება, ემიტენტი, რეგისტრაციის ქვეყანა
B40: 00320 | C40: 2.1 | D40: სასესხო ფასიანი ქაღალდის დასახელება, ემიტენტი, რეგისტრაციის ქვეყანა
B41: 00330 | C41: 2.11 | D41: სასესხო ფასიანი ქაღალდის დასახელება, ემიტენტი, რეგისტრაციის ქვეყანა
B42: 00340 | C42: 2.12 | D42: სასესხო ფასიანი ქაღალდის დასახელება, ემიტენტი, რეგისტრაციის ქვეყანა
... B49: 00410 | C49: 2.19 | D49: სასესხო ფასიანი ქაღალდის დასახელება, ემიტენტი, რეგისტრაციის ქვეყანა
B50: 00420 | C50: 2.20 | D50: სასესხო ფასიანი ქაღალდის დასახელება, ემიტენტი, რეგისტრაციის ქვეყანა
B51: 00430 | C51: 3 | D51: კორპორაციული სასესხო ფასიანი ქაღალდები | E51: =SUM(E52:E71) -> 0 | F51: =SUM(F52:F71) -> 0
B52: 00440 | C52: 3.1 | D52: სასესხო ფასიანი ქაღალდის დასახელება, ემიტენტი, რეგისტრაციის ქვეყანა
B53: 00450 | C53: 3.2 | D53: სასესხო ფასიანი ქაღალდის დასახელება, ემიტენტი, რეგისტრაციის ქვეყანა
B54: 00460 | C54: 3.3 | D54: სასესხო ფასიანი ქაღალდის დასახელება, ემიტენტი, რეგისტრაციის ქვეყანა
...

Sheet BS-IR & RR
B1: მზღვეველი: | E1: ფორმა N1-4
B2: ანგარიშგების თარიღი:
D4: სადაზღვევო და გადაზღვევის მოთხოვნები
E5: ლარებში
B6: სტრიქონის კოდი | C6: N | E6: საანგარიშო პერიოდი | F6: გასული წლის შესაბამისი პერიოდი
C8: სადაზღვევო მოთხოვნები
B10: 00010 | C10: 1 | D10: სადაზღვევო მოთხოვნები
B11: 00020 | C11: 2 | D11: მინუს: სადაზღვევო დებიტორების გაუფასურების რეზერვი
B12: 00030 | C12: 3 | D12: სადაზღვევო მოთხოვნები, წმინდა (1-2) | E12: =E10-E11 -> 0 | F12: =F10-F11 -> 0
B13: 00040 | C13: 4 | D13: სადაზღვევო მოთხოვნები ბროკერებისგან
B14: 00050 | C14: 5 | D14: მინუს: ბროკერების დებიტორების გაუფასურების რეზერვი
B15: 00060 | C15: 6 | D15: სადაზღვევო მოთხოვნები ბროკერებისგან, წმინდა (4-5) | E15: =E13-E14 -> 0 | F15: =F13-F14 -> 0
B16: 00070 | C16: 7 | D16: სადაზღვევო მოთხოვნები აგენტებისგან
B17: 00080 | C17: 8 | D17: მინუს: აგენტების დებიტორების გაუფასურების რეზერვი
B18: 00090 | C18: 9 | D18: სადაზღვევო მოთხოვნები აგენტებისგან, წმინდა (7-8) | E18: =E16-E17 -> 0 | F18: =F16-F17 -> 0
B19: 00100 | C19: სულ სადაზღვევო მოთხოვნები, წმინდა: (3+6+9) | E19: =E12+E15+E18 -> 0 | F19: =F12+F15+F18 -> 0
C21: გადაზღვევის მოთხოვნები
B23: 00110 | C23: 10 | D23: ანაზღაურებულ ზარალებთან დაკავშირებული მოთხოვნები გადაზღვევიდან
B24: 00120 | C24: 11 | D24: მინუს: გადაზღვევის დებიტორების გაუფასურების რეზერვი
B25: 00130 | C25: 12 | D25: ანაზღაურებულ ზარალებთან დაკავშირებული მოთხოვნები გადაზღვევიდან, წმინდა (10-11) | E25: =E23-E24 -> 0 | F25: =F23-F24 -> 0
B26: 00140 | C26: 13 | D26: სხვა მოთხოვნები გადაზღვევიდან
B27: 00150 | C27: 14 | D27: მინუს: გადაზღვევის დებიტორების გაუფასურების რეზერვი
B28: 00160 | C28: 15 | D28: სხვა მოთხოვნები გადაზღვევიდან, წმინდა (13-14) | E28: =E26-E27 -> 0 | F28: =F26-F27 -> 0
B29: 00170 | C29: 16 | D29: გადაზღვევის მოთხოვნები ბროკერებისგან
B30: 00180 | C30: 17 | D30: მინუს: ბროკერების დებიტორების გაუფასურების რეზერვი
B31: 00190 | C31: 18 | D31: გადაზღვევის მოთხოვნები ბროკერებისგან, წმინდა (16-17) | E31: =E29-E30 -> 0 | F31: =F29-F30 -> 0
B32: 00200 | C32: 19 | D32: გადაზღვევის მოთხოვნები აგენტებისგან
B33: 00210 | C33: 20 | D33: მინუს: აგენტების დებიტორების გაუფასურების რეზერვი
B34: 00220 | C34: 21 | D34: გადაზღვევის მოთხოვნები აგენტებისგან, წმინდა (19-20) | E34: =E32-E33 -> 0 | F34: =F32-F33 -> 0
B35: 00230 | C35: სულ გადაზღვევის მოთხოვნები, წმინდა: (12+15+18+21) | E35: =E25+E28+E31+E34 -> 0 | F35: =F25+F28+F31+F34 -> 0

Sheet BS-L
B1: მზღვეველი: | P1: ფორმა N1-5
B2: ანგარიშგების თარიღი:
D4: გაცემული სესხები
P5: ლარებში
B6: სტრიქონის კოდი | C6: N | E6: საანგარიშო პერიოდი | L6: გასული წლის შესაბამისი პერიოდი
E7: ლარი | F7: დოლარი | G7: ევრო | H7: სხვა | I7: სულ | J7: რეზერვი | K7: სულ (ნეტო) | L7: ლარი | M7: დოლარი | N7: ევრო | O7: სხვა | P7: სულ | Q7: რეზერვი | R7: სულ (ნეტო)
B9: 00010 | C9: 1 | D9: უზრუნველყოფილი სესხები (მოკლევადიანი) | E9: =E10+E31+E52+E73+E94+E115 -> 0 | F9: =F10+F31+F52+F73+F94+F115 -> 0 | G9: =G10+G31+G52+G73+G94+G115 -> 0 | H9: =H10+H31+H52+H73+H94+H115 -> 0 | I9: =I10+I31+I52+I73+I94+I115 -> 0 | J9: =J10+J31+J52+J73+J94+J115 -> 0 | K9: =K10+K31+K52+K73+K94+K115 -> 0 | L9: =L10+L31+L52+L73+L94+L115 -> 0 | ... R9: =R10+R31+R52+R73+R94+R115 -> 0
B10: 00020 | C10: 1.1 | D10: უძრავი ქონებით უზრუნველყოფილი | E10: =SUM(E11:E30) -> 0 | F10: =SUM(F11:F30) -> 0 | G10: =SUM(G11:G30) -> 0 | H10: =SUM(H11:H30) -> 0 | I10: =SUM(E10:H10) -> 0 | J10: =SUM(J11:J30) -> 0 | K10: =I10-J10 -> 0 | L10: =SUM(L11:L30) -> 0 | M10: =SUM(M11:M30) -> 0 | N10: =SUM(N11:N30) -> 0 | O10: =SUM(O11:O30) -> 0 | P10: =SUM(L10:O10) -> 0 | Q10: =SUM(Q11:Q30) -> 0 | R10: =P10-Q10 -> 0
B11: 00030 | C11: 1.1.1 | D11: მსესხებელი, უძრავი ქონების დასახელება და ადგილმდებარეობა | I11: =SUM(E11:H11) -> 0 | K11: =I11-J11 -> 0 | P11: =SUM(L11:O11) -> 0 | R11: =P11-Q11 -> 0
B12: 00040 | C12: 1.1.2 | D12: მსესხებელი, უძრავი ქონების დასახელება და ადგილმდებარეობა | I12: =SUM(E12:H12) -> 0 | K12: =I12-J12 -> 0 | P12: =SUM(L12:O12) -> 0 | R12: =P12-Q12 -> 0
B13: 00050 | C13: 1.1.3 | D13: მსესხებელი, უძრავი ქონების დასახელება და ადგილმდებარეობა | I13: =SUM(E13:H13) -> 0 | K13: =I13-J13 -> 0 | P13: =SUM(L13:O13) -> 0 | R13: =P13-Q13 -> 0
B14: 00060 | C14: 1.1.4 | D14: მსესხებელი, უძრავი ქონების დასახელება და ადგილმდებარეობა | I14: =SUM(E14:H14) -> 0 | K14: =I14-J14 -> 0 | P14: =SUM(L14:O14) -> 0 | R14: =P14-Q14 -> 0
B15: 00070 | C15: 1.1.5 | D15: მსესხებელი, უძრავი ქონების დასახელება და ადგილმდებარეობა | I15: =SUM(E15:H15) -> 0 | K15: =I15-J15 -> 0 | P15: =SUM(L15:O15) -> 0 | R15: =P15-Q15 -> 0
B16: 00080 | C16: 1.1.6 | D16: მსესხებელი, უძრავი ქონების დასახელება და ადგილმდებარეობა | I16: =SUM(E16:H16) -> 0 | K16: =I16-J16 -> 0 | P16: =SUM(L16:O16) -> 0 | R16: =P16-Q16 -> 0
B17: 00090 | C17: 1.1.7 | D17: მსესხებელი, უძრავი ქონების დასახელება და ადგილმდებარეობა | I17: =SUM(E17:H17) -> 0 | K17: =I17-J17 -> 0 | P17: =SUM(L17:O17) -> 0 | R17: =P17-Q17 -> 0
B18: 00100 | C18: 1.1.8 | D18: მსესხებელი, უძრავი ქონების დასახელება და ადგილმდებარეობა | I18: =SUM(E18:H18) -> 0 | K18: =I18-J18 -> 0 | P18: =SUM(L18:O18) -> 0 | R18: =P18-Q18 -> 0
B19: 00110 | C19: 1.1.9 | D19: მსესხებელი, უძრავი ქონების დასახელება და ადგილმდებარეობა | I19: =SUM(E19:H19) -> 0 | K19: =I19-J19 -> 0 | P19: =SUM(L19:O19) -> 0 | R19: =P19-Q19 -> 0
B20: 00120 | C20: 1.1.10 | D20: მსესხებელი, უძრავი ქონების დასახელება და ადგილმდებარეობა | I20: =SUM(E20:H20) -> 0 | K20: =I20-J20 -> 0 | P20: =SUM(L20:O20) -> 0 | R20: =P20-Q20 -> 0
B21: 00130 | C21: 1.1.11 | D21: მსესხებელი, უძრავი ქონების დასახელება და ადგილმდებარეობა | I21: =SUM(E21:H21) -> 0 | K21: =I21-J21 -> 0 | P21: =SUM(L21:O21) -> 0 | R21: =P21-Q21 -> 0
B22: 00140 | C22: 1.1.12 | D22: მსესხებელი, უძრავი ქონების დასახელება და ადგილმდებარეობა | I22: =SUM(E22:H22) -> 0 | K22: =I22-J22 -> 0 | P22: =SUM(L22:O22) -> 0 | R22: =P22-Q22 -> 0
... B30: 00220 | C30: 1.1.20 | D30: მსესხებელი, უძრავი ქონების დასახელება და ადგილმდებარეობა | I30: =SUM(E30:H30) -> 0 | K30: =I30-J30 -> 0 | P30: =SUM(L30:O30) -> 0 | R30: =P30-Q30 -> 0
B31: 00230 | C31: 1.2 | D31: უძრავი ქონებით უზრუნველყოფილ სესხებზე დარიცხული % | E31: =SUM(E32:E51) -> 0 | F31: =SUM(F32:F51) -> 0 | G31: =SUM(G32:G51) -> 0 | H31: =SUM(H32:H51) -> 0 | I31: =SUM(E31:H31) -> 0 | J31: =SUM(J32:J51) -> 0 | K31: =I31-J31 -> 0 | L31: =SUM(L32:L51) -> 0 | M31: =SUM(M32:M51) -> 0 | N31: =SUM(N32:N51) -> 0 | O31: =SUM(O32:O51) -> 0 | P31: =SUM(L31:O31) -> 0 | Q31: =SUM(Q32:Q51) -> 0 | R31: =P31-Q31 -> 0
B32: 00240 | C32: 1.2.1 | D32: მსესხებელი, უძრავი ქონების დასახელება და ადგილმდებარეობა | I32: =SUM(E32:H32) -> 0 | K32: =I32-J32 -> 0 | P32: =SUM(L32:O32) -> 0 | R32: =P32-Q32 -> 0
B33: 00250 | C33: 1.2.2 | D33: მსესხებელი, უძრავი ქონების დასახელება და ადგილმდებარეობა | I33: =SUM(E33:H33) -> 0 | K33: =I33-J33 -> 0 | P33: =SUM(L33:O33) -> 0 | R33: =P33-Q33 -> 0
B34: 00260 | C34: 1.2.3 | D34: მსესხებელი, უძრავი ქონების დასახელება და ადგილმდებარეობა | I34: =SUM(E34:H34) -> 0 | K34: =I34-J34 -> 0 | P34: =SUM(L34:O34) -> 0 | R34: =P34-Q34 -> 0
B35: 00270 | C35: 1.2.4 | D35: მსესხებელი, უძრავი ქონების დასახელება და ადგილმდებარეობა | I35: =SUM(E35:H35) -> 0 | K35: =I35-J35 -> 0 | P35: =SUM(L35:O35) -> 0 | R35: =P35-Q35 -> 0
B36: 00280 | C36: 1.2.5 | D36: მსესხებელი, უძრავი ქონების დასახელება და ადგილმდებარეობა | I36: =SUM(E36:H36) -> 0 | K36: =I36-J36 -> 0 | P36: =SUM(L36:O36) -> 0 | R36: =P36-Q36 -> 0
B37: 00290 | C37: 1.2.6 | D37: მსესხებელი, უძრავი ქონების დასახელება და ადგილმდებარეობა | I37: =SUM(E37:H37) -> 0 | K37: =I37-J37 -> 0 | P37: =SUM(L37:O37) -> 0 | R37: =P37-Q37 -> 0
B38: 00300 | C38: 1.2.7 | D38: მსესხებელი, უძრავი ქონების დასახელება და ადგილმდებარეობა | I38: =SUM(E38:H38) -> 0 | K38: =I38-J38 -> 0 | P38: =SUM(L38:O38) -> 0 | R38: =P38-Q38 -> 0
B39: 00310 | C39: 1.2.8 | D39: მსესხებელი, უძრავი ქონების დასახელება და ადგილმდებარეობა | I39: =SUM(E39:H39) -> 0 | K39: =I39-J39 -> 0 | P39: =SUM(L39:O39) -> 0 | R39: =P39-Q39 -> 0
B40: 00320 | C40: 1.2.9 | D40: მსესხებელი, უძრავი ქონების დასახელება და ადგილმდებარეობა | I40: =SUM(E40:H40) -> 0 | K40: =I40-J40 -> 0 | P40: =SUM(L40:O40) -> 0 | R40: =P40-Q40 -> 0
B41: 00330 | C41: 1.2.10 | D41: მსესხებელი, უძრავი ქონების დასახელება და ადგილმდებარეობა | I41: =SUM(E41:H41) -> 0 | K41: =I41-J41 -> 0 | P41: =SUM(L41:O41) -> 0 | R41: =P41-Q41 -> 0
B42: 00340 | C42: 1.2.11 | D42: მსესხებელი, უძრავი ქონების დასახელება და ადგილმდებარეობა | I42: =SUM(E42:H42) -> 0 | K42: =I42-J42 -> 0 | P42: =SUM(L42:O42) -> 0 | R42: =P42-Q42 -> 0
B43: 00350 | C43: 1.2.12 | D43: მსესხებელი, უძრავი ქონების დასახელება და ადგილმდებარეობა | I43: =SUM(E43:H43) -> 0 | K43: =I43-J43 -> 0 | P43: =SUM(L43:O43) -> 0 | R43: =P43-Q43 -> 0
... B51: 00430 | C51: 1.2.20 | D51: მსესხებელი, უძრავი ქონების დასახელება და ადგილმდებარეობა | I51: =SUM(E51:H51) -> 0 | K51: =I51-J51 -> 0 | P51: =SUM(L51:O51) -> 0 | R51: =P51-Q51 -> 0
B52: 00440 | C52: 1.3 | D52: ფასიანი ქაღალდებით უზრუნველყოფილი | E52: =SUM(E53:E72) -> 0 | F52: =SUM(F53:F72) -> 0 | G52: =SUM(G53:G72) -> 0 | H52: =SUM(H53:H72) -> 0 | I52: =SUM(E52:H52) -> 0 | J52: =SUM(J53:J72) -> 0 | K52: =I52-J52 -> 0 | L52: =SUM(L53:L72) -> 0 | M52: =SUM(M53:M72) -> 0 | N52: =SUM(N53:N72) -> 0 | O52: =SUM(O53:O72) -> 0 | P52: =SUM(L52:O52) -> 0 | Q52: =SUM(Q53:Q72) -> 0 | R52: =P52-Q52 -> 0
B53: 00450 | C53: 1.3.1 | D53: მსესხებელი, ფასიანი ქაღალდის ტიპი, ემიტენტი | I53: =SUM(E53:H53) -> 0 | K53: =I53-J53 -> 0 | P53: =SUM(L53:O53) -> 0 | R53: =P53-Q53 -> 0
B54: 00460 | C54: 1.3.2 | D54: მსესხებელი, ფასიანი ქაღალდის ტიპი, ემიტენტი | I54: =SUM(E54:H54) -> 0 | K54: =I54-J54 -> 0 | P54: =SUM(L54:O54) -> 0 | R54: =P54-Q54 -> 0
B55: 00470 | C55: 1.3.3 | D55: მსესხებელი, ფასიანი ქაღალდის ტიპი, ემიტენტი | I55: =SUM(E55:H55) -> 0 | K55: =I55-J55 -> 0 | P55: =SUM(L55:O55) -> 0 | R55: =P55-Q55 -> 0
B56: 00480 | C56: 1.3.4 | D56: მსესხებელი, ფასიანი ქაღალდის ტიპი, ემიტენტი | I56: =SUM(E56:H56) -> 0 | K56: =I56-J56 -> 0 | P56: =SUM(L56:O56) -> 0 | R56: =P56-Q56 -> 0
...

Sheet BS-I
B1: მზღვეველი: | E1: ფორმა N1-6
B2: ანგარიშგების თარიღი:
D4: ინვესტიციები მეკავშირე და შვილობილ კომპანიებში
E5: ლარებში
B6: სტრიქონის კოდი | C6: N | E6: საანგარიშო პერიოდი | F6: გასული წლის შესაბამისი პერიოდი
C8: მეკავშირე კომპანიები
B10: 00010 | C10: 1 | D10: მონაწილეობა კაპიტალში | E10: =SUM(E11:E30) -> 0 | F10: =SUM(F11:F30) -> 0
B11: 00020 | C11: 1.1 | D11: წილობრივი ინსტრუმენტის დასახელება, ემიტენტი, რეგისტრაციის ქვეყანა
B12: 00030 | C12: 1.2 | D12: წილობრივი ინსტრუმენტის დასახელება, ემიტენტი, რეგისტრაციის ქვეყანა
B13: 00040 | C13: 1.3 | D13: წილობრივი ინსტრუმენტის დასახელება, ემიტენტი, რეგისტრაციის ქვეყანა
B14: 00050 | C14: 1.4 | D14: წილობრივი ინსტრუმენტის დასახელება, ემიტენტი, რეგისტრაციის ქვეყანა
B15: 00060 | C15: 1.5 | D15: წილობრივი ინსტრუმენტის დასახელება, ემიტენტი, რეგისტრაციის ქვეყანა
B16: 00070 | C16: 1.6 | D16: წილობრივი ინსტრუმენტის დასახელება, ემიტენტი, რეგისტრაციის ქვეყანა
B17: 00080 | C17: 1.7 | D17: წილობრივი ინსტრუმენტის დასახელება, ემიტენტი, რეგისტრაციის ქვეყანა
B18: 00090 | C18: 1.8 | D18: წილობრივი ინსტრუმენტის დასახელება, ემიტენტი, რეგისტრაციის ქვეყანა
B19: 00100 | C19: 1.9 | D19: წილობრივი ინსტრუმენტის დასახელება, ემიტენტი, რეგისტრაციის ქვეყანა
B20: 00110 | C20: 1.10 | D20: წილობრივი ინსტრუმენტის დასახელება, ემიტენტი, რეგისტრაციის ქვეყანა
B21: 00120 | C21: 1.11 | D21: წილობრივი ინსტრუმენტის დასახელება, ემიტენტი, რეგისტრაციის ქვეყანა
B22: 00130 | C22: 1.12 | D22: წილობრივი ინსტრუმენტის დასახელება, ემიტენტი, რეგისტრაციის ქვეყანა
B23: 00140 | C23: 1.13 | D23: წილობრივი ინსტრუმენტის დასახელება, ემიტენტი, რეგისტრაციის ქვეყანა
... B30: 00210 | C30: 1.20 | D30: წილობრივი ინსტრუმენტის დასახელება, ემიტენტი, რეგისტრაციის ქვეყანა
B31: 00220 | C31: 2 | D31: სასესხო ფასიანი ქაღალდები | E31: =E32+E53+E74+E95+E116+E137 -> 0 | F31: =F32+F53+F74+F95+F116+F137 -> 0
B32: 00230 | C32: 2.1 | D32: სასესხო ფასიანი ქაღალდები (მოკლევადიანი) | E32: =SUM(E33:E52) -> 0 | F32: =SUM(F33:F52) -> 0
B33: 00240 | C33: 2.1.1 | D33: სასესხო ფასიანი ქაღალდის დასახელება, ემიტენტი, რეგისტრაციის ქვეყანა
B34: 00250 | C34: 2.1.2 | D34: სასესხო ფასიანი ქაღალდის დასახელება, ემიტენტი, რეგისტრაციის ქვეყანა
B35: 00260 | C35: 2.1.3 | D35: სასესხო ფასიანი ქაღალდის დასახელება, ემიტენტი, რეგისტრაციის ქვეყანა
B36: 00270 | C36: 2.1.4 | D36: სასესხო ფასიანი ქაღალდის დასახელება, ემიტენტი, რეგისტრაციის ქვეყანა
B37: 00280 | C37: 2.1.5 | D37: სასესხო ფასიანი ქაღალდის დასახელება, ემიტენტი, რეგისტრაციის ქვეყანა
B38: 00290 | C38: 2.1.6 | D38: სასესხო ფასიანი ქაღალდის დასახელება, ემიტენტი, რეგისტრაციის ქვეყანა
B39: 00300 | C39: 2.1.7 | D39: სასესხო ფასიანი ქაღალდის დასახელება, ემიტენტი, რეგისტრაციის ქვეყანა
B40: 00310 | C40: 2.1.8 | D40: სასესხო ფასიანი ქაღალდის დასახელება, ემიტენტი, რეგისტრაციის ქვეყანა
B41: 00320 | C41: 2.1.9 | D41: სასესხო ფასიანი ქაღალდის დასახელება, ემიტენტი, რეგისტრაციის ქვეყანა
B42: 00330 | C42: 2.1.10 | D42: სასესხო ფასიანი ქაღალდის დასახელება, ემიტენტი, რეგისტრაციის ქვეყანა
B43: 00340 | C43: 2.1.11 | D43: სასესხო ფასიანი ქაღალდის დასახელება, ემიტენტი, რეგისტრაციის ქვეყანა
B44: 00350 | C44: 2.1.12 | D44: სასესხო ფასიანი ქაღალდის დასახელება, ემიტენტი, რეგისტრაციის ქვეყანა
... B52: 00430 | C52: 2.1.20 | D52: სასესხო ფასიანი ქაღალდის დასახელება, ემიტენტი, რეგისტრაციის ქვეყანა
B53: 00440 | C53: 2.2 | D53: სასესხო ფასიან ქაღალდებზე (მოკლევადიანი) დარიცხული % | E53: =SUM(E54:E73) -> 0 | F53: =SUM(F54:F73) -> 0
B54: 00450 | C54: 2.2.1 | D54: სასესხო ფასიანი ქაღალდის დასახელება, ემიტენტი, რეგისტრაციის ქვეყანა
B55: 00460 | C55: 2.2.2 | D55: სასესხო ფასიანი ქაღალდის დასახელება, ემიტენტი, რეგისტრაციის ქვეყანა
B56: 00470 | C56: 2.2.3 | D56: სასესხო ფასიანი ქაღალდის დასახელება, ემიტენტი, რეგისტრაციის ქვეყანა
...

Sheet BS-R
B1: მზღვეველი: | E1: ფორმა N1-7
B2: ანგარიშგების თარიღი:
C4: სადაზღვევო რეზერვები და გადამზღვევლის წილი სადაზღვევო რეზერვებში
E5: ლარებში
B6: სტრიქონის კოდი | C6: N | E6: საანგარიშო პერიოდი | F6: გასული წლის შესაბამისი პერიოდი
C8: არასიცოცხლის დაზღვევა
C9: სადაზღვევო რეზერვები (არასიცოცხლის), ბრუტო
B10: 00010 | C10: 1 | D10: - გამოუმუშავებელი პრემიის რეზერვი
B11: 00020 | C11: 2 | D11: - განცხადებული, მაგრამ დაურეგულირებელი ზარალების რეზერვი
B12: 00030 | C12: 3 | D12: - მომხდარი, მაგრამ განუცხადებელი ზარალების რეზერვი
B13: 00040 | C13: სულ სადაზღვევო რეზერვები, ბრუტო: (1+2+3) | E13: =E10+E11+E12 -> 0 | F13: =F10+F11+F12 -> 0
C15: გადამზღვევლის წილი სადაზღვევო რეზერვებში (არასიცოცხლის)
B16: 00050 | C16: 4 | D16: - გამოუმუშავებელი პრემიიის რეზერვი
B17: 00060 | C17: 5 | D17: - განცხადებული, მაგრამ დაურეგულირებელი ზარალების რეზერვი
B18: 00070 | C18: სულ გადამზღვევლის წილი სადაზღვევო რეზერვებში: (4+5) | E18: =SUM(E16:E17) -> 0 | F18: =SUM(F16:F17) -> 0
C20: სადაზღვევო რეზერვები (არასიცოცხლის), ნეტო
B21: 00080 | C21: 6 | D21: - გამოუმუშავებელი პრემიიის რეზერვი (1-4) | E21: =E10-E16 -> 0 | F21: =F10-F16 -> 0
B22: 00090 | C22: 7 | D22: - განცხადებული, მაგრამ დაურეგულირებელი ზარალების რეზერვი (2-5) | E22: =E11-E17 -> 0 | F22: =F11-F17 -> 0
B23: 00100 | C23: 8 | D23: - მომხდარი, მაგრამ განუცხადებელი ზარალების რეზერვი (=3) | E23: =E12 -> 0 | F23: =F12 -> 0
B24: 00110 | C24: სულ სადაზღვევო რეზერვები, ნეტო: (6+7+8) | E24: =E21+E22+E23 -> 0 | F24: =F21+F22+F23 -> 0
C26: სიცოცხლის დაზღვევა
C27: სადაზღვევო რეზერვები (სიცოცხლის), ბრუტო
B28: 00120 | C28: 9 | D28: - გამოუმუშავებელი პრემიის რეზერვი
B29: 00130 | C29: 10 | D29: - განცხადებული, მაგრამ დაურეგულირებელი ზარალების რეზერვი
B30: 00140 | C30: 11 | D30: - მომხდარი, მაგრამ განუცხადებელი ზარალების რეზერვი
B31: 00150 | C31: 12 | D31: - სიცოცხლის დაზღვევის რეზერვი
B32: 00160 | C32: სულ სადაზღვევო რეზერვები, ბრუტო: (9+10+11+12) | E32: =SUM(E28:E31) -> 0 | F32: =SUM(F28:F31) -> 0
C34: გადამზღვევლის წილი სადაზღვევო რეზერვებში (სიცოცხლის)
B35: 00170 | C35: 13 | D35: - გამოუმუშავებელი პრემიის რეზერვი
B36: 00180 | C36: 14 | D36: - განცხადებული, მაგრამ დაურეგულირებელი ზარალების რეზერვი
B37: 00190 | C37: 15 | D37: - სიცოცხლის დაზღვევის რეზერვი
B38: 00200 | C38: სულ გადამზღვევლის წილი სადაზღვევო რეზერვებში: (13+14+15) | E38: =SUM(E35:E37) -> 0 | F38: =SUM(F35:F37) -> 0
C40: სადაზღვევო რეზერვები (სიცოცხლის), ნეტო
B41: 00210 | C41: 16 | D41: - გამოუმუშავებელი პრემიის რეზერვი (9-13) | E41: =E28-E35 -> 0 | F41: =F28-F35 -> 0
B42: 00220 | C42: 17 | D42: - განცხადებული, მაგრამ დაურეგულირებელი ზარალების რეზერვი (10-14) | E42: =E29-E36 -> 0 | F42: =F29-F36 -> 0
B43: 00230 | C43: 18 | D43: - მომხდარი, მაგრამ განუცხადებელი ზარალების რეზერვი (=11) | E43: =E30 -> 0 | F43: =F30 -> 0
B44: 00240 | C44: 19 | D44: - სიცოცხლის დაზღვევის რეზერვი (12-15) | E44: =E31-E37 -> 0 | F44: =F31-F37 -> 0
B45: 00250 | C45: სულ სადაზღვევო რეზერვები, ნეტო: (16+17+18+19) | E45: =SUM(E41:E44) -> 0 | F45: =SUM(F41:F44) -> 0

Sheet BS-DC
B1: მზღვეველი: | E1: ფორმა N1-8
B2: ანგარიშგების თარიღი:
C4: გადავადებული საკომისიო შემოსავალი/ხარჯი
E5: ლარებში
B6: სტრიქონის კოდი | C6: N | E6: საანგარიშო პერიოდი | F6: გასული წლის შესაბამისი პერიოდი
C8: არასიცოცხლის დაზღვევა
C9: გადავადებული საკომისიო ხარჯი (არასიცოცხლის)
B10: 00010 | C10: 1 | D10: - ცედენტის კუთვნილი საკომისიო
B11: 00020 | C11: 2 | D11: - ბროკერის კუთვნილი საკომისიო
B12: 00030 | C12: 3 | D12: - აგენტის კუთვნილი საკომისიო
B13: 00040 | C13: სულ გადავადებული საკომისიო ხარჯი (არასიცოცხლის): (1+2+3) | E13: =E10+E11+E12 -> 0 | F13: =F10+F11+F12 -> 0
C15: გადავადებული საკომისიო შემოსავალი (არასიცოცხლის)
B16: 00050 | C16: 4 | D16: - გადაზღვევიდან კუთვნილი საკომისიო
B17: 00060 | C17: სულ გადავადებული საკომისიო შემოსავალი (არასიცოცხლის): (=4) | E17: =SUM(E16:E16) -> 0 | F17: =SUM(F16:F16) -> 0
C19: სიცოცხლის დაზღვევა
C20: გადავადებული საკომისიო ხარჯი (სიცოცხლის)
B21: 00070 | C21: 5 | D21: - ცედენტის კუთვნილი საკომისიო
B22: 00080 | C22: 6 | D22: - ბროკერის კუთვნილი საკომისიო
B23: 00090 | C23: 7 | D23: - აგენტის კუთვნილი საკომისიო
B24: 00100 | C24: სულ გადავადებული საკომისიო ხარჯი (სიცოცხლის): (5+6+7) | E24: =SUM(E21:E23) -> 0 | F24: =SUM(F21:F23) -> 0
C26: გადავადებული საკომისიო შემოსავალი (სიცოცხლის)
B27: 00110 | C27: 8 | D27: - გადაზღვევიდან კუთვნილი საკომისიო
B28: 00120 | C28: სულ გადავადებული საკომისიო შემოსავალი (სიცოცხლის): (=8) | E28: =SUM(E27:E27) -> 0 | F28: =SUM(F27:F27) -> 0

Sheet BS-PPE
B1: მზღვეველი: | K1: ფორმა N1-9
B2: ანგარიშგების თარიღი:
C4: ძირითადი საშუალებების წმინდა საბალანსო ღირებულების განსაზღვრა
K5: ლარებში
B6: სტრიქონის კოდი | C6: N | E6: მიწა | F6: შენობები | G6: ავტო -ტრანსპორტი | H6: კომპიუტერები და კომუნიკაციები | I6: ავეჯი და სხვა მოწყობილობა | J6: დაუმთავრებელი მშენებლობა | K6: სხვა | L6: სულ
B8: 00010 | C8: ისტორიული ღირებულება ან გადაფასება
B9: 00020 | C9: 1 | D9: ნაშთი პერიოდის დასაწყისში | L9: =E9+F9+G9+H9+I9+J9+K9 -> 0
B10: 00030 | C10: აკუმულირებული ცვეთა
B11: 00040 | C11: 2 | D11: ნაშთი პერიოდის დასაწყისში | L11: =E11+F11+G11+H11+I11+J11+K11 -> 0
B12: 00050 | C12: 3 | D12: ნაშთი პერიოდის დასაწყისში (1-2) | E12: =E9-E11 -> 0 | F12: =F9-F11 -> 0 | G12: =G9-G11 -> 0 | H12: =H9-H11 -> 0 | I12: =I9-I11 -> 0 | J12: =J9-J11 -> 0 | K12: =K9-K11 -> 0 | L12: =L9-L11 -> 0
B13: 00060 | C13: 4 | D13: მოძრაობა კატეგორიებს შორის (ზრდა/კლება) | L13: =E13+F13+G13+H13+I13+J13+K13 -> 0
B14: 00070 | C14: 5 | D14: შესყიდვები | L14: =E14+F14+G14+H14+I14+J14+K14 -> 0
B15: 00080 | C15: 6 | D15: ჩამოწერა/გაყიდვა | L15: =E15+F15+G15+H15+I15+J15+K15 -> 0
B16: 00090 | C16: 7 | D16: გადაფასება (ზრდა/კლება) | L16: =E16+F16+G16+H16+I16+J16+K16 -> 0
B17: 00100 | C17: 8 | D17: ცვეთის ხარჯი | L17: =E17+F17+G17+H17+I17+J17+K17 -> 0
B18: 00110 | C18: 9 | D18: ნაშთი პერიოდის ბოლოს (3+4+5-6+7-8) | E18: =E12+E13+E14-E15+E16-E17 -> 0 | F18: =F12+F13+F14-F15+F16-F17 -> 0 | G18: =G12+G13+G14-G15+G16-G17 -> 0 | H18: =H12+H13+H14-H15+H16-H17 -> 0 | I18: =I12+I13+I14-I15+I16-I17 -> 0 | J18: =J12+J13+J14-J15+J16-J17 -> 0 | K18: =K12+K13+K14-K15+K16-K17 -> 0 | L18: =L12+L13+L14-L15+L16-L17 -> 0

Sheet BS-IP & OA
B1: მზღვეველი: | E1: ფორმა N1-10
B2: ანგარიშგების თარიღი:
D4: საინვესტიციო ქონება და სხვა აქტივები
E5: ლარებში
B6: სტრიქონის კოდი | C6: N | E6: საანგარიშო პერიოდი | F6: გასული წლის შესაბამისი პერიოდი
C8: საინვესტიციო ქონება
B10: 00010 | C10: 1 | D10: მიწები | E10: =SUM(E11:E30) -> 0 | F10: =SUM(F11:F30) -> 0
B11: 00020 | C11: 1.1 | D11: ობიექტის დასახელება, ობიექტის რეგისტრაციის ქვეყანა
B12: 00030 | C12: 1.2 | D12: ობიექტის დასახელება, ობიექტის რეგისტრაციის ქვეყანა
B13: 00040 | C13: 1.3 | D13: ობიექტის დასახელება, ობიექტის რეგისტრაციის ქვეყანა
B14: 00050 | C14: 1.4 | D14: ობიექტის დასახელება, ობიექტის რეგისტრაციის ქვეყანა
B15: 00060 | C15: 1.5 | D15: ობიექტის დასახელება, ობიექტის რეგისტრაციის ქვეყანა
B16: 00070 | C16: 1.6 | D16: ობიექტის დასახელება, ობიექტის რეგისტრაციის ქვეყანა
B17: 00080 | C17: 1.7 | D17: ობიექტის დასახელება, ობიექტის რეგისტრაციის ქვეყანა
B18: 00090 | C18: 1.8 | D18: ობიექტის დასახელება, ობიექტის რეგისტრაციის ქვეყანა
B19: 00100 | C19: 1.9 | D19: ობიექტის დასახელება, ობიექტის რეგისტრაციის ქვეყანა
B20: 00110 | C20: 1.1 | D20: ობიექტის დასახელება, ობიექტის რეგისტრაციის ქვეყანა
B21: 00120 | C21: 1.11 | D21: ობიექტის დასახელება, ობიექტის რეგისტრაციის ქვეყანა
B22: 00130 | C22: 1.12 | D22: ობიექტის დასახელება, ობიექტის რეგისტრაციის ქვეყანა
... B30: 00210 | C30: 1.2 | D30: ობიექტის დასახელება, ობიექტის რეგისტრაციის ქვეყანა
B31: 00220 | C31: 2 | D31: შენობა-ნაგებობები | E31: =SUM(E32:E51) -> 0 | F31: =SUM(F32:F51) -> 0
B32: 00230 | C32: 2.1 | D32: ობიექტის დასახელება, ობიექტის რეგისტრაციის ქვეყანა
B33: 00240 | C33: 2.2 | D33: ობიექტის დასახელება, ობიექტის რეგისტრაციის ქვეყანა
B34: 00250 | C34: 2.3 | D34: ობიექტის დასახელება, ობიექტის რეგისტრაციის ქვეყანა
B35: 00260 | C35: 2.4 | D35: ობიექტის დასახელება, ობიექტის რეგისტრაციის ქვეყანა
B36: 00270 | C36: 2.5 | D36: ობიექტის დასახელება, ობიექტის რეგისტრაციის ქვეყანა
B37: 00280 | C37: 2.6 | D37: ობიექტის დასახელება, ობიექტის რეგისტრაციის ქვეყანა
B38: 00290 | C38: 2.7 | D38: ობიექტის დასახელება, ობიექტის რეგისტრაციის ქვეყანა
B39: 00300 | C39: 2.8 | D39: ობიექტის დასახელება, ობიექტის რეგისტრაციის ქვეყანა
B40: 00310 | C40: 2.9 | D40: ობიექტის დასახელება, ობიექტის რეგისტრაციის ქვეყანა
B41: 00320 | C41: 2.1 | D41: ობიექტის დასახელება, ობიექტის რეგისტრაციის ქვეყანა
B42: 00330 | C42: 2.11 | D42: ობიექტის დასახელება, ობიექტის რეგისტრაციის ქვეყანა
B43: 00340 | C43: 2.12 | D43: ობიექტის დასახელება, ობიექტის რეგისტრაციის ქვეყანა
... B51: 00420 | C51: 2.2 | D51: ობიექტის დასახელება, ობიექტის რეგისტრაციის ქვეყანა
B52: 00430 | C52: 3 | D52: სხვა | E52: =SUM(E53:E72) -> 0 | F52: =SUM(F53:F72) -> 0
B53: 00440 | C53: 3.1 | D53: ობიექტის დასახელება, ობიექტის რეგისტრაციის ქვეყანა
B54: 00450 | C54: 3.2 | D54: ობიექტის დასახელება, ობიექტის რეგისტრაციის ქვეყანა
B55: 00460 | C55: 3.3 | D55: ობიექტის დასახელება, ობიექტის რეგისტრაციის ქვეყანა
B56: 00470 | C56: 3.4 | D56: ობიექტის დასახელება, ობიექტის რეგისტრაციის ქვეყანა
B57: 00480 | C57: 3.5 | D57: ობიექტის დასახელება, ობიექტის რეგისტრაციის ქვეყანა
...

Sheet BS-IA
B1: მზღვეველი: | H1: ფორმა N1-11
B2: ანგარიშგების თარიღი:
C4: არამატერიალური აქტივების წმინდა საბალანსო ღირებულების განსაზღვრა
H5: ლარებში
B6: სტრიქონის კოდი | C6: N | E6: გუდვილი | F6: ლიცენზიები | G6: კომპიუტერული პროგრამები | H6: სხვა | I6: სულ
B8: 00010 | C8: ისტორიული ღირებულება ან გადაფასება
B9: 00020 | C9: 1 | D9: ნაშთი პერიოდის დასაწყისში | I9: =E9+F9+G9+H9 -> 0
B10: 00030 | C10: აკუმულირებული ცვეთა
B11: 00040 | C11: 2 | D11: ნაშთი პერიოდის დასაწყისში | I11: =E11+F11+G11+H11 -> 0
B12: 00050 | C12: 3 | D12: ნაშთი პერიოდის დასაწყისში (1-2) | E12: =E9-E11 -> 0 | F12: =F9-F11 -> 0 | G12: =G9-G11 -> 0 | H12: =H9-H11 -> 0 | I12: =I9-I11 -> 0
B13: 00060 | C13: 4 | D13: მოძრაობა კატეგორიებს შორის (ზრდა/კლება) | I13: =E13+F13+G13+H13 -> 0
B14: 00070 | C14: 5 | D14: შესყიდვები | I14: =E14+F14+G14+H14 -> 0
B15: 00080 | C15: 6 | D15: ჩამოწერა/გაყიდვა | I15: =E15+F15+G15+H15 -> 0
B16: 00090 | C16: 7 | D16: გადაფასება (ზრდა/კლება) | I16: =E16+F16+G16+H16 -> 0
B17: 00100 | C17: 8 | D17: გუდვილის გაუფასურება | I17: =E17+F17+G17+H17 -> 0
B18: 00110 | C18: 9 | D18: ცვეთის ხარჯი | I18: =E18+F18+G18+H18 -> 0
B19: 00120 | C19: 10 | D19: ნაშთი პერიოდის ბოლოს (3+4+5-6+7-8-9) | E19: =E12+E13+E14-E15+E16-E17-E18 -> 0 | F19: =F12+F13+F14-F15+F16-F17-F18 -> 0 | G19: =G12+G13+G14-G15+G16-G17-G18 -> 0 | H19: =H12+H13+H14-H15+H16-H17-H18 -> 0 | I19: =I12+I13+I14-I15+I16-I17-I18 -> 0

Sheet BS-OIL & OL
B1: მზღვეველი: | E1: ფორმა N1-12
B2: ანგარიშგების თარიღი:
D4: სხვა ვალდებულებები
E5: ლარებში
B6: სტრიქონის კოდი | C6: N | E6: საანგარიშო პერიოდი | F6: გასული წლის შესაბამისი პერიოდი
C8: სხვა სადაზღვევო ვალდებულებები
B10: 00010 | C10: 1 | D10: გადასახდელი გადაზღვევის პრემია
B11: 00020 | C11: 2 | D11: გადამზღვევლისგან მიღებული ავანსები (სადაზღვევო ზარალებთან დაკავშირებული)
B12: 00030 | C12: 3 | D12: გადაზღვევით მიღებულ შემოსავალთან დაკავშირებული საკომისიო
B13: 00040 | C13: 4 | D13: გადასახდელი ბროკერის საკომისიო
B14: 00050 | C14: 5 | D14: გადასახდელი აგენტის საკომისიო
B15: 00060 | C15: სულ სხვა სადაზღვევო ვალდებულებები: (1+2+3+4+5) | E15: =E10+E11+E12+E13+E14 -> 0 | F15: =F10+F11+F12+F13+F14 -> 0
C17: სხვა ვალდებულებები
B19: 00070 | C19: 1 | D19: შესრულებულ სამუშაოზე და მოწოდებულ მომსახურებაზე დარიცხული ვალდებულებები
B20: 00080 | C20: 2 | D20: გადასახდელი ხელფასები
B21: 00090 | C21: 3 | D21: მიღებული ავანსები
B22: 00100 | C22: 4 | D22: გადასახდელი მოგების გადასახადი
B23: 00110 | C23: =C22+1 -> 5 | D23: სხვა გადასახდელი გადასახადები: | E23: =E24+E25+E26+E27 -> 0 | F23: =F24+F25+F26+F27 -> 0
B24: 00120 | C24: 5.1 | D24: გადასახდელი დღგ
B25: 00130 | C25: 5.2 | D25: გადასახდელი საშემოსავლო გადასახადი
B26: 00140 | C26: 5.3 | D26: გადასახდელი ქონების გადასახადი
B27: 00150 | C27: 5.4 | D27: სხვა
B28: 00160 | C28: 6 | D28: გადასახდელი დივიდენდები
B29: 00170 | C29: 7 | D29: სხვა
B30: 00180 | C30: სხვა ვალდებულებები სულ: (1+2+3+4+5+6+7) | E30: =E19+E20+E21+E22+E23+E28+E29 -> 0 | F30: =F19+F20+F21+F22+F23+F28+F29 -> 0

Sheet BS-FL
B1: მზღვეველი: | M1: ფორმა N1-13
B2: ანგარიშგების თარიღი:
D4: ფინანსური ვალდებულებები
M5: ლარებში
B6: სტრიქონის კოდი | C6: N | E6: საანგარიშო პერიოდი | J6: გასული წლის შესაბამისი პერიოდი
E7: ლარი | F7: დოლარი | G7: ევრო | H7: სხვა | I7: სულ | J7: ლარი | K7: დოლარი | L7: ევრო | M7: სხვა | N7: სულ
B9: 00010 | C9: 1 | D9: ბანკის სესხები | E9: =E10+E31+E52+E73+E94+E115 -> 0 | F9: =F10+F31+F52+F73+F94+F115 -> 0 | G9: =G10+G31+G52+G73+G94+G115 -> 0 | H9: =H10+H31+H52+H73+H94+H115 -> 0 | I9: =I10+I31+I52+I73+I94+I115 -> 0 | J9: =J10+J31+J52+J73+J94+J115 -> 0 | K9: =K10+K31+K52+K73+K94+K115 -> 0 | L9: =L10+L31+L52+L73+L94+L115 -> 0 | ... N9: =N10+N31+N52+N73+N94+N115 -> 0
B10: 00020 | C10: 1.1 | D10: ბანკის სესხები (მოკლევადიანი) | E10: =SUM(E11:E30) -> 0 | F10: =SUM(F11:F30) -> 0 | G10: =SUM(G11:G30) -> 0 | H10: =SUM(H11:H30) -> 0 | I10: =SUM(E10:H10) -> 0 | J10: =SUM(J11:J30) -> 0 | K10: =SUM(K11:K30) -> 0 | L10: =SUM(L11:L30) -> 0 | M10: =SUM(M11:M30) -> 0 | N10: =SUM(J10:M10) -> 0
B11: 00030 | C11: 1.1.1 | D11: ბანკის დასახელება | I11: =SUM(E11:H11) -> 0 | N11: =SUM(J11:M11) -> 0
B12: 00040 | C12: 1.1.2 | D12: ბანკის დასახელება | I12: =SUM(E12:H12) -> 0 | N12: =SUM(J12:M12) -> 0
B13: 00050 | C13: 1.1.3 | D13: ბანკის დასახელება | I13: =SUM(E13:H13) -> 0 | N13: =SUM(J13:M13) -> 0
B14: 00060 | C14: 1.1.4 | D14: ბანკის დასახელება | I14: =SUM(E14:H14) -> 0 | N14: =SUM(J14:M14) -> 0
B15: 00070 | C15: 1.1.5 | D15: ბანკის დასახელება | I15: =SUM(E15:H15) -> 0 | N15: =SUM(J15:M15) -> 0
B16: 00080 | C16: 1.1.6 | D16: ბანკის დასახელება | I16: =SUM(E16:H16) -> 0 | N16: =SUM(J16:M16) -> 0
B17: 00090 | C17: 1.1.7 | D17: ბანკის დასახელება | I17: =SUM(E17:H17) -> 0 | N17: =SUM(J17:M17) -> 0
B18: 00100 | C18: 1.1.8 | D18: ბანკის დასახელება | I18: =SUM(E18:H18) -> 0 | N18: =SUM(J18:M18) -> 0
B19: 00110 | C19: 1.1.9 | D19: ბანკის დასახელება | I19: =SUM(E19:H19) -> 0 | N19: =SUM(J19:M19) -> 0
B20: 00120 | C20: 1.1.10 | D20: ბანკის დასახელება | I20: =SUM(E20:H20) -> 0 | N20: =SUM(J20:M20) -> 0
B21: 00130 | C21: 1.1.11 | D21: ბანკის დასახელება | I21: =SUM(E21:H21) -> 0 | N21: =SUM(J21:M21) -> 0
B22: 00140 | C22: 1.1.12 | D22: ბანკის დასახელება | I22: =SUM(E22:H22) -> 0 | N22: =SUM(J22:M22) -> 0
... B30: 00220 | C30: 1.1.20 | D30: ბანკის დასახელება | I30: =SUM(E30:H30) -> 0 | N30: =SUM(J30:M30) -> 0
B31: 00230 | C31: 1.2 | D31: ბანკის სესხებზე (მოკლევადიანი) დარიცხული % | E31: =SUM(E32:E51) -> 0 | F31: =SUM(F32:F51) -> 0 | G31: =SUM(G32:G51) -> 0 | H31: =SUM(H32:H51) -> 0 | I31: =SUM(E31:H31) -> 0 | J31: =SUM(J32:J51) -> 0 | K31: =SUM(K32:K51) -> 0 | L31: =SUM(L32:L51) -> 0 | M31: =SUM(M32:M51) -> 0 | N31: =SUM(J31:M31) -> 0
B32: 00240 | C32: 1.2.1 | D32: ბანკის დასახელება | I32: =SUM(E32:H32) -> 0 | N32: =SUM(J32:M32) -> 0
B33: 00250 | C33: 1.2.2 | D33: ბანკის დასახელება | I33: =SUM(E33:H33) -> 0 | N33: =SUM(J33:M33) -> 0
B34: 00260 | C34: 1.2.3 | D34: ბანკის დასახელება | I34: =SUM(E34:H34) -> 0 | N34: =SUM(J34:M34) -> 0
B35: 00270 | C35: 1.2.4 | D35: ბანკის დასახელება | I35: =SUM(E35:H35) -> 0 | N35: =SUM(J35:M35) -> 0
B36: 00280 | C36: 1.2.5 | D36: ბანკის დასახელება | I36: =SUM(E36:H36) -> 0 | N36: =SUM(J36:M36) -> 0
B37: 00290 | C37: 1.2.6 | D37: ბანკის დასახელება | I37: =SUM(E37:H37) -> 0 | N37: =SUM(J37:M37) -> 0
B38: 00300 | C38: 1.2.7 | D38: ბანკის დასახელება | I38: =SUM(E38:H38) -> 0 | N38: =SUM(J38:M38) -> 0
B39: 00310 | C39: 1.2.8 | D39: ბანკის დასახელება | I39: =SUM(E39:H39) -> 0 | N39: =SUM(J39:M39) -> 0
B40: 00320 | C40: 1.2.9 | D40: ბანკის დასახელება | I40: =SUM(E40:H40) -> 0 | N40: =SUM(J40:M40) -> 0
B41: 00330 | C41: 1.2.10 | D41: ბანკის დასახელება | I41: =SUM(E41:H41) -> 0 | N41: =SUM(J41:M41) -> 0
B42: 00340 | C42: 1.2.11 | D42: ბანკის დასახელება | I42: =SUM(E42:H42) -> 0 | N42: =SUM(J42:M42) -> 0
B43: 00350 | C43: 1.2.12 | D43: ბანკის დასახელება | I43: =SUM(E43:H43) -> 0 | N43: =SUM(J43:M43) -> 0
... B51: 00430 | C51: 1.2.20 | D51: ბანკის დასახელება | I51: =SUM(E51:H51) -> 0 | N51: =SUM(J51:M51) -> 0
B52: 00440 | C52: 1.3 | D52: ბანკის სესხების (გრძელვადიანი) მიმდინარე წილი | E52: =SUM(E53:E72) -> 0 | F52: =SUM(F53:F72) -> 0 | G52: =SUM(G53:G72) -> 0 | H52: =SUM(H53:H72) -> 0 | I52: =SUM(E52:H52) -> 0 | J52: =SUM(J53:J72) -> 0 | K52: =SUM(K53:K72) -> 0 | L52: =SUM(L53:L72) -> 0 | M52: =SUM(M53:M72) -> 0 | N52: =SUM(J52:M52) -> 0
B53: 00450 | C53: 1.3.1 | D53: ბანკის დასახელება | I53: =SUM(E53:H53) -> 0 | N53: =SUM(J53:M53) -> 0
B54: 00460 | C54: 1.3.2 | D54: ბანკის დასახელება | I54: =SUM(E54:H54) -> 0 | N54: =SUM(J54:M54) -> 0
B55: 00470 | C55: 1.3.3 | D55: ბანკის დასახელება | I55: =SUM(E55:H55) -> 0 | N55: =SUM(J55:M55) -> 0
B56: 00480 | C56: 1.3.4 | D56: ბანკის დასახელება | I56: =SUM(E56:H56) -> 0 | N56: =SUM(J56:M56) -> 0
...

Sheet BS-PL
B1: მზღვეველი: | E1: ფორმა N1-14
B2: ანგარიშგების თარიღი:
D4: საპენსიო ვალდებულებები
E5: ლარებში
B6: სტრიქონის კოდი | C6: N | E6: საანგარიშო პერიოდი | F6: გასული წლის შესაბამისი პერიოდი
C8: სქემა განსაზღვრული შენატანით
B10: 00010 | C10: 1 | D10: საპენსიო ვალდებულებები პერიოდის დასაწყისში
B11: 00020 | C11: 2 | D11: პერიოდის განმავლობაში მიღებული საპენსიო შენატანები
B12: 00030 | C12: 3 | D12: სხვა საპენსიო სქემიდან გადმოტანილი სახსრები
B13: 00040 | C13: 4 | D13: საპენსიო სქემიდან გატანილი სახსრები
B14: 00050 | C14: 5 | D14: გაცემული პენსიები
B15: 00060 | C15: 6 | D15: საპენსიო ვალდებულება საინვესტიციო საქმიანობამდე (1+2+3-4-5) | E15: =E10+E11+E12-E13-E14 -> 0 | F15: =F10+F11+F12-F13-F14 -> 0
B16: 00070 | C16: 7 | D16: საინვესტიციო შემოსავალი
B17: 00080 | C17: 8 | D17: გაწევრიანების საკომისიო
B18: 00090 | C18: 9 | D18: ადმინისტრაციული საკომისიო
B19: 00100 | C19: 10 | D19: აქტივების მართვის საკომისიო
B20: 00110 | C20: 11 | D20: სხვა ხარჯები
B21: 00120 | C21: 12 | D21: სხვა შემოსავლები
B22: 00130 | C22: 13 | D22: საპენსიო ვალდებულებები პერიოდის ბოლოს: (6+7-8-9-10-11+12) | E22: =E15+E16-E17-E18-E19-E20+E21 -> 0 | F22: =F15+F16-F17-F18-F19-F20+F21 -> 0
C24: სქემა განსაზღვრული პენსიით
B26: 00140 | C26: 14 | D26: საპენსიო ვალდებულებები პერიოდის დასაწყისში
B27: 00150 | C27: 15 | D27: საპენსიო ვალდებულებები პერიოდის ბოლოს:

Sheet BS-LA
B1: მზღვეველი: | E1: ფორმა N1-15
B2: ანგარიშგების თარიღი:
D4: ვალდებულებები მეკავშირე და შვილობილ კომპანიებთან
E5: ლარებში
B6: სტრიქონის კოდი | C6: N | E6: საანგარიშო პერიოდი | F6: გასული წლის შესაბამისი პერიოდი
C8: მეკავშირე კომპანიები
B10: 00010 | C10: 1 | D10: სესხები | E10: =E11+E32+E53+E74+E95+E116 -> 0 | F10: =F11+F32+F53+F74+F95+F116 -> 0
B11: 00020 | C11: 1.1 | D11: მოკლევადიანი სესხები | E11: =SUM(E12:E31) -> 0 | F11: =SUM(F12:F31) -> 0
B12: 00030 | C12: 1.1.1 | D12: კომპანიის დასახელება
B13: 00040 | C13: 1.1.2 | D13: კომპანიის დასახელება
B14: 00050 | C14: 1.1.3 | D14: კომპანიის დასახელება
B15: 00060 | C15: 1.1.4 | D15: კომპანიის დასახელება
B16: 00070 | C16: 1.1.5 | D16: კომპანიის დასახელება
B17: 00080 | C17: 1.1.6 | D17: კომპანიის დასახელება
B18: 00090 | C18: 1.1.7 | D18: კომპანიის დასახელება
B19: 00100 | C19: 1.1.8 | D19: კომპანიის დასახელება
B20: 00110 | C20: 1.1.9 | D20: კომპანიის დასახელება
B21: 00120 | C21: 1.1.10 | D21: კომპანიის დასახელება
B22: 00130 | C22: 1.1.11 | D22: კომპანიის დასახელება
B23: 00140 | C23: 1.1.12 | D23: კომპანიის დასახელება
... B31: 00220 | C31: 1.1.20 | D31: კომპანიის დასახელება
B32: 00230 | C32: 1.2 | D32: მოკლევადიან სესხებზე დარიცხული % | E32: =SUM(E33:E52) -> 0 | F32: =SUM(F33:F52) -> 0
B33: 00240 | C33: 1.2.1 | D33: კომპანიის დასახელება
B34: 00250 | C34: 1.2.2 | D34: კომპანიის დასახელება
B35: 00260 | C35: 1.2.3 | D35: კომპანიის დასახელება
B36: 00270 | C36: 1.2.4 | D36: კომპანიის დასახელება
B37: 00280 | C37: 1.2.5 | D37: კომპანიის დასახელება
B38: 00290 | C38: 1.2.6 | D38: კომპანიის დასახელება
B39: 00300 | C39: 1.2.7 | D39: კომპანიის დასახელება
B40: 00310 | C40: 1.2.8 | D40: კომპანიის დასახელება
B41: 00320 | C41: 1.2.9 | D41: კომპანიის დასახელება
B42: 00330 | C42: 1.2.10 | D42: კომპანიის დასახელება
B43: 00340 | C43: 1.2.11 | D43: კომპანიის დასახელება
B44: 00350 | C44: 1.2.12 | D44: კომპანიის დასახელება
... B52: 00430 | C52: 1.2.20 | D52: კომპანიის დასახელება
B53: 00440 | C53: 1.3 | D53: გრძელვადიანი სესხების მიმდინარე წილი | E53: =SUM(E54:E73) -> 0 | F53: =SUM(F54:F73) -> 0
B54: 00450 | C54: 1.3.1 | D54: კომპანიის დასახელება
B55: 00460 | C55: 1.3.2 | D55: კომპანიის დასახელება
B56: 00470 | C56: 1.3.3 | D56: კომპანიის დასახელება
B57: 00480 | C57: 1.3.4 | D57: კომპანიის დასახელება
...

Sheet IS
B1: მზღვეველი: | E1: ფორმა N2
B2: ანგარიშგების პერიოდი:
D4: სრული შემოსავლის ანგარიშგება (მოგება-ზარალის უწყისი)
E5: ლარებში
B6: სტრიქონის კოდი | C6: N | E6: საანგარიშო პერიოდი | F6: გასული წლის შესაბამისი პერიოდი
C8: I. სადაზღვევო საქმიანობა (არასიცოცხლე)
B9: 00010 | C9: 1 | D9: - მოზიდული პრემია, ბრუტო | E9: ='P&C(NL)'!L45+'P&C(NL)'!I232 -> 0 | F9: ='P&C(NL)'!T45+'P&C(NL)'!Q232 -> 0
B10: 00020 | C10: 2 | D10: - გადაზღვევის პრემია | E10: ='P&C(NL)'!I91+'P&C(NL)'!I279 -> 0 | F10: ='P&C(NL)'!Q91+'P&C(NL)'!Q279 -> 0
B11: 00030 | C11: 3 | D11: - ცვლილება გამოუმუშავებელი პრემიის რეზერვში, ბრუტო
B12: 00040 | C12: 4 | D12: - ცვლილება გამოუმუშავებელი პრემიის რეზერვში, გადამზღვევლის წილი
B13: 00050 | C13: 5 | D13: - გამომუშავებული პრემია (ნეტო)/სადაზღვევო შემოსავალი (1-2-3+4) | E13: =E9-E10-E11+E12 -> 0 | F13: =F9-F10-F11+F12 -> 0
B14: 00060 | C14: 6 | D14: - ანაზღაურებული ზარალები | E14: ='P&C(NL)'!L139+'P&C(NL)'!I326 -> 0 | F14: ='P&C(NL)'!T139+'P&C(NL)'!Q326 -> 0
B15: 00070 | C15: 7 | D15: - გადამზღვევლის წილი ანაზღაურებულ ზარალებში | E15: ='P&C(NL)'!K186+'P&C(NL)'!I373 -> 0 | F15: ='P&C(NL)'!S186+'P&C(NL)'!Q373 -> 0
B16: 00080 | C16: 8 | D16: - ცვლილება ზარალების რეზერვში, ბრუტო
B17: 00090 | C17: 9 | D17: - ცვლილება ზარალების რეზერვში, გადამზღვევლის წილი
B18: 00100 | C18: 10 | D18: - შემოსავალი რეგრესიდან და გადარჩენილი ქონებიდან, ნეტო
B19: 00110 | C19: 11 | D19: - სადაზღვევო/დამდგარი ზარალები, ნეტო (6-7+8-9-10) | E19: =E14-E15+E16-E17-E18 -> 0 | F19: =F14-F15+F16-F17-F18 -> 0
B20: 00120 | C20: 12 | D20: - დარიცხული ბონუსები
B21: 00130 | C21: 13 | D21: - საკომისიო შემოსავალი (ხარჯი), წმინდა | E21: ='IS-COM'!E26 -> 0 | F21: ='IS-COM'!F26 -> 0
B22: 00140 | C22: 14 | D22: სადაზღვევო მოგება (ზარალი), წმინდა (5-11-12+13) | E22: =E13-E19-E20+E21 -> 0 | F22: =F13-F19-F20+F21 -> 0
C24: II. სადაზღვევო საქმიანობა (სიცოცხლე)
B25: 00150 | C25: 15 | D25: - მოზიდული პრემია, ბრუტო | E25: ='P&C(L)'!L15+'P&C(L)'!I69 -> 0 | F25: ='P&C(L)'!T15+'P&C(L)'!Q69 -> 0
B26: 00160 | C26: 16 | D26: - გადაზღვევის პრემია | E26: ='P&C(L)'!I26+'P&C(L)'!I80 -> 0 | F26: ='P&C(L)'!Q26+'P&C(L)'!Q80 -> 0
B27: 00170 | C27: 17 | D27: - ცვლილება გამოუმუშავებელი პრემიის რეზერვში, ბრუტო
B28: 00180 | C28: 18 | D28: - ცვლილება გამოუმუშავებელი პრემიის რეზერვში, გადამზღვევლის წილი
B29: 00190 | C29: 19 | D29: - გამომუშავებული პრემია (ნეტო)/სადაზღვევო შემოსავალი (15-16-17+18) | E29: =E25-E26-E27+E28 -> 0 | F29: =F25-F26-F27+F28 -> 0
B30: 00200 | C30: 20 | D30: - ანაზღაურებული ზარალები | E30: ='P&C(L)'!L38+'P&C(L)'!I91 -> 0 | F30: ='P&C(L)'!T38+'P&C(L)'!Q91 -> 0
B31: 00210 | C31: 21 | D31: - გადამზღვევლის წილი ანაზღაურებულ ზარალებში | E31: ='P&C(L)'!K50+'P&C(L)'!E102 -> 0 | F31: ='P&C(L)'!S50+'P&C(L)'!M102 -> 0
B32: 00220 | C32: 22 | D32: - ცვლილება ზარალების რეზერვში, ბრუტო
B33: 00230 | C33: 23 | D33: - ცვლილება ზარალების რეზერვში, გადამზღვევლის წილი
B34: 00240 | C34: 24 | D34: - შემოსავალი რეგრესიდან (სიცოცხლის)
B35: 00250 | C35: 25 | D35: - სადაზღვევო/დამდგარი ზარალები, ნეტო (20-21+22-23-24) | E35: =E30-E31+E32-E33-E34 -> 0 | F35: =F30-F31+F32-F33-F34 -> 0
B36: 00260 | C36: 26 | D36: - ცვლილება სიცოცხლის დაზღვევის რეზერვში, ბრუტო
B37: 00270 | C37: 27 | D37: - ცვლილება სიცოცხლის დაზღვევის რეზერვში, გადამზღვევლის წილი
B38: 00280 | C38: 28 | D38: - ცვლილება სიცოცხლის რეზერვში, ნეტო (26-27) | E38: =E36-E37 -> 0 | F38: =F36-F37 -> 0
B39: 00290 | C39: 29 | D39: - დარიცხული ბონუსები (სიცოცხლის)
B40: 00300 | C40: 30 | D40: - საკომისიო შემოსავალი (ხარჯი), წმინდა | E40: ='IS-COM'!E46 -> 0 | F40: ='IS-COM'!F46 -> 0
B41: 00310 | C41: 31 | D41: სადაზღვევო მოგება (ზარალი), წმინდა (19-25+28-29+30) | E41: =E29-E35+E38-E39+E40 -> 0 | F41: =F29-F35+F38-F39+F40 -> 0
B43: 00320 | C43: 32 | D43: სადაზღვევო მოგება (ზარალი), წმინდა (14+31) | E43: =E22+E41 -> 0 | F43: =F22+F41 -> 0
D45: III. საპენსიო საქმიანობა
...

Sheet IS-COM
B1: მზღვეველი: | E1: ფორმა N2-1
B2: ანგარიშგების პერიოდი:
D4: საკომისიო შემოსავალი (ხარჯი)
E5: ლარებში
B6: სტრიქონის კოდი | C6: N | E6: საანგარიშო პერიოდი | F6: გასული წლის შესაბამისი პერიოდი
C8: არასიცოცხლის დაზღვევა
B10: 00010 | C10: 1 | D10: გადაზღვევიდან კუთვნილი საკომისიო
B11: 00020 | C11: 2 | D11: გადაზღვევიდან კუთვნილი საკომისიო (გადავადებას დაქვემდებარებული)
B12: 00030 | C12: 3 | D12: ცვლილება გადავადებულ შემოსავალში (გადაზღვევიდან კუთვნილი საკომისიო)
B13: 00040 | C13: 4 | D13: გადამზღვევლისაგან მიღებული საკომისიო, წმინდა (1+2-3) | E13: =E10+E11-E12 -> 0 | F13: =F10+F11-F12 -> 0
B14: 00050 | C14: 5 | D14: ცედენტის კუთვნილი საკომისიო
B15: 00060 | C15: 6 | D15: ცედენტის კუთვნილი საკომისიო (გადავადებას დაქვემდებარებული)
B16: 00070 | C16: 7 | D16: ცვლილება გადავადებულ ხარჯში (ცედენტის კუთვნილი საკომისიო)
B17: 00080 | C17: 8 | D17: ცედენტის კუთვნილი საკომისიო, წმინდა (5+6-7) | E17: =E14+E15-E16 -> 0 | F17: =F14+F15-F16 -> 0
B18: 00090 | C18: 9 | D18: ბროკერის კუთვნილი საკომისიო
B19: 00100 | C19: 10 | D19: ბროკერის კუთვნილი საკომისიო (გადავადებას დაქვემდებარებული)
B20: 00110 | C20: 11 | D20: ცვლილება გადავადებულ ხარჯში (ბროკერის კუთვნილი საკომისიო)
B21: 00120 | C21: 12 | D21: ბროკერის საკომისიო, წმინდა (9+10-11) | E21: =E18+E19-E20 -> 0 | F21: =F18+F19-F20 -> 0
B22: 00130 | C22: 13 | D22: აგენტის კუთვნილი საკომისიო
B23: 00140 | C23: 14 | D23: აგენტის კუთვნილი საკომისიო (გადავადებას დაქვემდებარებული)
B24: 00150 | C24: 15 | D24: ცვლილება გადავადებულ ხარჯში (აგენტის კუთვნილი საკომისიო)
B25: 00160 | C25: 16 | D25: აგენტის საკომისიო, წმინდა (13+14-15) | E25: =E22+E23-E24 -> 0 | F25: =F22+F23-F24 -> 0
B26: 00170 | C26: საკომისიო შემოსავალი (ხარჯი), წმინდა (4-8-12-16) | E26: =E13-E17-E21-E25 -> 0 | F26: =F13-F17-F21-F25 -> 0
C28: სიცოცხლის დაზღვევა
B30: 00180 | C30: 17 | D30: გადაზღვევიდან კუთვნილი საკომისიო
B31: 00190 | C31: 18 | D31: გადაზღვევიდან კუთვნილი საკომისიო (გადავადებას დაქვემდებარებული)
B32: 00200 | C32: 19 | D32: ცვლილება გადავადებულ შემოსავალში (გადაზღვევიდან კუთვნილი საკომისიო)
B33: 00210 | C33: 20 | D33: გადამზღვევლისაგან მიღებული საკომისიო, წმინდა (17+18-19) | E33: =E30+E31-E32 -> 0 | F33: =F30+F31-F32 -> 0
B34: 00220 | C34: 21 | D34: ცედენტის კუთვნილი საკომისიო
B35: 00230 | C35: 22 | D35: ცედენტის კუთვნილი საკომისიო (გადავადებას დაქვემდებარებული)
B36: 00240 | C36: 23 | D36: ცვლილება გადავადებულ ხარჯში (ცედენტის კუთვნილი საკომისიო)
B37: 00250 | C37: 24 | D37: ცედენტის კუთვნილი საკომისიო, წმინდა (21+22-23) | E37: =E34+E35-E36 -> 0 | F37: =F34+F35-F36 -> 0
B38: 00260 | C38: 25 | D38: ბროკერის კუთვნილი საკომისიო
B39: 00270 | C39: 26 | D39: ბროკერის კუთვნილი საკომისიო (გადავადებას დაქვემდებარებული)
B40: 00280 | C40: 27 | D40: ცვლილება გადავადებულ ხარჯში (ბროკერის კუთვნილი საკომისიო)
B41: 00290 | C41: 28 | D41: ბროკერის საკომისიო, წმინდა (25+26-27) | E41: =E38+E39-E40 -> 0 | F41: =F38+F39-F40 -> 0
B42: 00300 | C42: 29 | D42: აგენტის კუთვნილი საკომისიო
B43: 00310 | C43: 30 | D43: აგენტის კუთვნილი საკომისიო (გადავადებას დაქვემდებარებული)
B44: 00320 | C44: 31 | D44: ცვლილება გადავადებულ ხარჯში (აგენტის კუთვნილი საკომისიო)
B45: 00330 | C45: 32 | D45: აგენტის საკომისიო, წმინდა (29+30-31) | E45: =E42+E43-E44 -> 0 | F45: =F42+F43-F44 -> 0
...

Sheet IS-D
B1: მზღვეველი: | E1: ფორმა N2-2
B2: ანგარიშგების პერიოდი:
D4: შემოსავალი საკრედიტო დაწესებულებებში განთავსებული ფულადი სახსრებიდან
E5: ლარებში
B6: სტრიქონის კოდი | C6: N | E6: საანგარიშო პერიოდი | F6: გასული წლის შესაბამისი პერიოდი
B8: 00010 | C8: 1 | D8: - მიმდინარე ანგარიშებიდან (2+3+4+5) | E8: =E9+E52+E95+E138 -> 0 | F8: =F9+F52+F95+F138 -> 0
B9: 00020 | C9: 2 | D9: ლარი | E9: =E10+E31 -> 0 | F9: =F10+F31 -> 0
B10: 00030 | C10: 2.1 | D10: რეზიდენტ ბანკებში | E10: =SUM(E11:E30) -> 0 | F10: =SUM(F11:F30) -> 0
B11: 00040 | C11: 2.1.1 | D11: ბანკის დასახელება, ბანკის რეგისტრაციის ქვეყანა
B12: 00050 | C12: 2.1.2 | D12: ბანკის დასახელება, ბანკის რეგისტრაციის ქვეყანა
B13: 00060 | C13: 2.1.3 | D13: ბანკის დასახელება, ბანკის რეგისტრაციის ქვეყანა
B14: 00070 | C14: 2.1.4 | D14: ბანკის დასახელება, ბანკის რეგისტრაციის ქვეყანა
B15: 00080 | C15: 2.1.5 | D15: ბანკის დასახელება, ბანკის რეგისტრაციის ქვეყანა
B16: 00090 | C16: 2.1.6 | D16: ბანკის დასახელება, ბანკის რეგისტრაციის ქვეყანა
B17: 00100 | C17: 2.1.7 | D17: ბანკის დასახელება, ბანკის რეგისტრაციის ქვეყანა
B18: 00110 | C18: 2.1.8 | D18: ბანკის დასახელება, ბანკის რეგისტრაციის ქვეყანა
B19: 00120 | C19: 2.1.9 | D19: ბანკის დასახელება, ბანკის რეგისტრაციის ქვეყანა
B20: 00130 | C20: 2.1.10 | D20: ბანკის დასახელება, ბანკის რეგისტრაციის ქვეყანა
B21: 00140 | C21: 2.1.11 | D21: ბანკის დასახელება, ბანკის რეგისტრაციის ქვეყანა
B22: 00150 | C22: 2.1.12 | D22: ბანკის დასახელება, ბანკის რეგისტრაციის ქვეყანა
... B30: 00230 | C30: 2.1.20 | D30: ბანკის დასახელება, ბანკის რეგისტრაციის ქვეყანა
B31: 00240 | C31: 2.2 | D31: არარეზიდენტ ბანკებში | E31: =SUM(E32:E51) -> 0 | F31: =SUM(F32:F51) -> 0
B32: 00250 | C32: 2.2.1 | D32: ბანკის დასახელება, ბანკის რეგისტრაციის ქვეყანა
B33: 00260 | C33: 2.2.2 | D33: ბანკის დასახელება, ბანკის რეგისტრაციის ქვეყანა
B34: 00270 | C34: 2.2.3 | D34: ბანკის დასახელება, ბანკის რეგისტრაციის ქვეყანა
B35: 00280 | C35: 2.2.4 | D35: ბანკის დასახელება, ბანკის რეგისტრაციის ქვეყანა
B36: 00290 | C36: 2.2.5 | D36: ბანკის დასახელება, ბანკის რეგისტრაციის ქვეყანა
B37: 00300 | C37: 2.2.6 | D37: ბანკის დასახელება, ბანკის რეგისტრაციის ქვეყანა
B38: 00310 | C38: 2.2.7 | D38: ბანკის დასახელება, ბანკის რეგისტრაციის ქვეყანა
B39: 00320 | C39: 2.2.8 | D39: ბანკის დასახელება, ბანკის რეგისტრაციის ქვეყანა
B40: 00330 | C40: 2.2.9 | D40: ბანკის დასახელება, ბანკის რეგისტრაციის ქვეყანა
B41: 00340 | C41: 2.2.10 | D41: ბანკის დასახელება, ბანკის რეგისტრაციის ქვეყანა
B42: 00350 | C42: 2.2.11 | D42: ბანკის დასახელება, ბანკის რეგისტრაციის ქვეყანა
B43: 00360 | C43: 2.2.12 | D43: ბანკის დასახელება, ბანკის რეგისტრაციის ქვეყანა
... B51: 00440 | C51: 2.2.20 | D51: ბანკის დასახელება, ბანკის რეგისტრაციის ქვეყანა
B52: 00450 | C52: 3 | D52: აშშ დოლარი | E52: =E53+E74 -> 0 | F52: =F53+F74 -> 0
B53: 00460 | C53: 3.1 | D53: რეზიდენტ ბანკებში | E53: =SUM(E54:E73) -> 0 | F53: =SUM(F54:F73) -> 0
B54: 00470 | C54: 3.1.1 | D54: ბანკის დასახელება, ბანკის რეგისტრაციის ქვეყანა
B55: 00480 | C55: 3.1.2 | D55: ბანკის დასახელება, ბანკის რეგისტრაციის ქვეყანა
B56: 00490 | C56: 3.1.3 | D56: ბანკის დასახელება, ბანკის რეგისტრაციის ქვეყანა
...

Sheet IS-FA
B1: მზღვეველი: | E1: ფორმა N2-3
B2: ანგარიშგების პერიოდი:
D4: შემოსავალი ფინანსური აქტივებიდან
E5: ლარებში
B6: სტრიქონის კოდი | C6: N | E6: საანგარიშო პერიოდი | F6: გასული წლის შესაბამისი პერიოდი
