Workbook

Sheet რეზერვები
B1: ფორმა N 11
B2: სადაზღვევო რეზერვები საანგარიშო თარიღისათვის
B4: კომპანიის დასახელება: ___________________________________
B5: საანგარიშო თარიღი: ___________________________________
J6: ლარი
A7: სახეობის კოდი | B7: დაზღვევის სახეობა | C7: გამოუმუშავებელი პრემიის რეზერვი (ბრუტო) | D7: გამოუმუშავებელი პრემიის რეზერვი (ნეტო) | E7: განცხადებული, მაგრამ დაურეგულირებელი ზარალების რეზერვი (ბრუტო) | F7: განცხადებული, მაგრამ დაურეგულირებელი ზარალების რეზერვი (ნეტო) | G7: მომხდარი, მაგრამ განუცხადებელი ზარალების რეზერვი | H7: სადაზღვევო რეზერვი მაგროვებადი და დაბრუნებადი სიცოცხლის დაზღვევის სახეობებისათვის - სიცოცხლის დაზღვევის რეზერვი (ბრუტო) | I7: სადაზღვევო რეზერვი მაგროვებადი და დაბრუნებადი სიცოცხლის დაზღვევის სახეობებისათვის - სიცოცხლის დაზღვევის რეზერვი (ნეტო) | J7: არასახელმწიფო საპენსიო დაზღვევის რეზერვი – საპენსიო ვალდებულებები
A8: 01 | B8: სიცოცხლის დაზღვევა: | C8: =SUM(C9:C12) -> 0 | D8: =SUM(D9:D12) -> 0 | E8: =SUM(E9:E12) -> 0 | F8: =SUM(F9:F12) -> 0 | G8: =SUM(G9:G12) -> 0 | H8: =SUM(H9:H12) -> 0 | I8: =SUM(I9:I12) -> 0
B9: სიცოცხლის ვადიანი დაზღვევა
B10: სიცოცხლის უვადო დაზღვევა
B11: სიცოცხლის დაზღვევის მაგროვებადი და დაბრუნებადი სახეობები
B12: სიცოცხლის დაზღვევის სხვა ფორმები
A13: 02 | B13: სამოგზაურო დაზღვევა
A14: 03 | B14: უბედური შემთხვევის დაზღვევა: | C14: =SUM(C15:C16) -> 0 | D14: =SUM(D15:D16) -> 0 | E14: =SUM(E15:E16) -> 0 | F14: =SUM(F15:F16) -> 0 | G14: =SUM(G15:G16) -> 0
B15: დაზღვევა უბედური შემთხვევებისაგან
B16: მგზავრების, მძღოლის ან ეკიპაჟის დაზღვევა უბედური შემთხვევებისაგან
A17: 04 | B17: სამედიცინო (ჯანმრთელობის) დაზღვევა
A18: 05 | B18: სახმელეთო სატრანსპორტო საშუალებათა დაზღვევა (გარდა სარკინიგზო ტრანსპორტისა): | C18: =SUM(C19:C20) -> 0 | D18: =SUM(D19:D20) -> 0 | E18: =SUM(E19:E20) -> 0 | F18: =SUM(F19:F20) -> 0 | G18: =SUM(G19:G20) -> 0
B19: სახმელეთო ავტოსატრანსპორტო საშუალებათა დაზღვევა (ავტოკასკო):
B20: სხვა სახმელეთო სატრანსპორტო საშუალებათა დაზღვევა
A21: 06 | B21: სახმელეთო ტრანსპორტის გამოყენებასთან დაკავშირებული სამოქალაქო პასუხისმგებლობის დაზღვევა: | C21: =SUM(C22:C24) -> 0 | D21: =SUM(D22:D24) -> 0 | E21: =SUM(E22:E24) -> 0 | F21: =SUM(F22:F24) -> 0 | G21: =SUM(G22:G24) -> 0
B22: ავტომოტოტრანსპორტის მფლობელთა სამოქალაქო პასუხისმგებლობის სავალდებულო დაზღვევა
B23: სახმელეთო ტრანსპორტის გამოყენებასთან დაკავშირებული სამოქალაქო პასუხისმგებლობის დაზღვევა
B24: სახმელეთო გადამზიდველის სამოქალაქო პასუხისმგებლობის დაზღვევა
A25: 07 | B25: სარკინიგზო სატრანსპორტო საშუალებათა დაზღვევა
A26: 08 | B26: საჰაერო სატრანსპორტო საშუალებათა დაზღვევა (კორპუსის დაზღვევა)
A27: 09 | B27: საჰაერო სატრანსპორტო საშუალებათა გამოყენებასთან დაკავშირებული პასუხისმგებლობის დაზღვევა: | C27: =SUM(C28:C29) -> 0 | D27: =SUM(D28:D29) -> 0 | E27: =SUM(E28:E29) -> 0 | F27: =SUM(F28:F29) -> 0 | G27: =SUM(G28:G29) -> 0
B28: საჰაერო გადამზიდველის პასუხისმგებლობის დაზღვევა
B29: სხვა პასუხისმგებლობის დაზღვევა, რომელიც დაკავშირებულია საჰაერო ტრანსპორტის გამოყენებასთან
A30: 10 | B30: მცურავი სატრანსპორტო საშუალებების დაზღვევა (კორპუსის დაზღვევა)
A31: 11 | B31: მცურავ სატრანსპორტო საშუალებათა გამოყენებასთან დაკავშირებული პასუხისმგებლობის დაზღვევა | C31: =SUM(C32:C33) -> 0 | D31: =SUM(D32:D33) -> 0 | E31: =SUM(E32:E33) -> 0 | F31: =SUM(F32:F33) -> 0 | G31: =SUM(G32:G33) -> 0
B32: საზღვაო გადამზიდველის პასუხისმგებლობის დაზღვევა
B33: სხვა პასუხისმგებლობის დაზღვევა, რომელიც დაკავშირებულია მცურავი ტრანსპორტის გამოყენებასთან
A34: 12 | B34: ტვირთების დაზღვევა
A35: 13 | B35: ქონების დაზღვევა (გარდა პპ. (5), (7), (8), (10), და (12)-ში ჩამოთვლილი ქონებისა):
A36: 14 | B36: დაზღვევა საფინანსო დანაკარგებისაგან
A37: 15 | B37: ვალდებულებათა შესრულების დაზღვევა | C37: =SUM(C38:C40) -> 0 | D37: =SUM(D38:D40) -> 0 | E37: =SUM(E38:E40) -> 0 | F37: =SUM(F38:F40) -> 0 | G37: =SUM(G38:G40) -> 0
B38: საბაჟო ვალდებულებების შესრულების გარანტიები/ფინანსური რისკის დაზღვევის პოლისები
B39: სახელმწიფო შესყიდვებთან დაკავშირებული გარანტიები
B40: სხვა სახის გარანტიები
A41: 16 | B41: საკრედიტო ვალდებულებათა დაზღვევა
...

Sheet ინვ. დაქვ. რეზერვ. ოდენობა
B1: ფორმა N 12
B2: A1, A2, A3, A4, A5, A6, A7, A8, A9, A10, A11 და A12 აქტივებში ინვესტირებას დაქვემდებარებული სადაზღვევო რეზერვების ოდენობის განსაზღვრა
B4: =რეზერვები!B4 -> კომპანიის დასახელება: ___________________________________
B5: =რეზერვები!B5 -> საანგარიშო თარიღი: ___________________________________
D6: ლარი
B7: გამოუმუშავებელი პრემიის რეზერვის ინვესტირებას დაქვემდებარებული ოდენობა | C7: 0.75 | D7: =((D8-D9-D10+D11-D12)*C7) -> 0
B8: გამოუმუშავებელი პრემიის რეზერვი | D8: =რეზერვები!C48 -> 0
B9: გადამზღვევლის წილი გამოუმუშავებელი პრემიის რეზერვში | D9: =რეზერვები!C48-რეზერვები!D48 -> 0
B10: სადაზღვევო მოთხოვნები წმინდა (ფინანსური ანგარიშგების ფორმა N 1-4, სულ სადაზღვევო მოთხოვნები, წმინდა-00100 )
B11: ვალდებულებები გადაზღვევის მიმართ (ფინანსური ანგარიშგების ფორმა N 1-12, გადასახდელი გადაზღვევის პრემია–00010_სა და გადამზღვევლისგან მიღებული ავანსები (სადაზღვევო ზარალებთან დაკავშირებული)–00020_ს ჯამი)
B12: გადაზღვევის მოთხოვნები, (ფინანსური ანგარიშგების ფორმა N 1-4, სულ გადაზღვევის მოთხოვნები, წმინდა - 00230_სა და ანაზღაურებულ ზარალებთან დაკავშირებული მოთხოვნები გადაზღვევიდან, წმინდა–00130–ს სხვაობა)
B15: განცხადებული, მაგრამ დაურეგულირებელი ზარალების რეზერვის ინვესტირებას დაქვემდებარებული ოდენობა | C15: 1 | D15: =(D16-D17-D18+D19-D20-D21)*C15 -> 0
B16: რეზერვის ოდენობა | D16: =რეზერვები!E48 -> 0
B17: გადამზღვევლის წილი | D17: =რეზერვები!E48-რეზერვები!F48 -> 0
B18: ანაზღაურებულ ზარალებთან დაკავშირებული მოთხოვნები გადაზღვევიდან
B19: მოთხოვნები გადაზღვევიდან, სადაც მზღვეველის მიერ ზარალის სრული ოდენობის ანაზღაურების თარიღიდან 1 წელზე მეტი დროის პერიოდია გასული
B20: მზღვეველის დავალიანება სამედიცინო მომსახურების მიმწოდებლებთან საქართველოს მთავრობის 2009 წლის 9 დეკემბრის N218 დადგენილების ფარგლებში
B21: მზღვეველის დავალიანება სამედიცინო მომსახურების მიმწოდებლებთან საქართველოს მთავრობის 2012 წლის 7 მაისის N165 დადგენილების ფარგლებში
B23: მომხდარი, მაგრამ განუცხადებელი ზარალების რეზერვის ინვესტირებას დაქვემდებარებული ოდენობა | C23: 1 | D23: =(D24-D25-D26)*C23 -> 0
B24: მომხდარი, მაგრამ განუცხადებელი ზარალების რეზერვი | D24: =რეზერვები!G48 -> 0
B25: მომხდარი, მაგრამ განუცხადებელი ზარალების რეზერვის ოდენობა საქართველოს მთავრობის 2009 წლის 9 დეკემბრის N218 დადგენილების ფარგლებში
B26: მომხდარი, მაგრამ განუცხადებელი ზარალების რეზერვის ოდენობა საქართველოს მთავრობის 2012 წლის 7 მაისის N165 დადგენილების ფარგლებში
B28: საპენსიო ვალდებულებების ინვესტირებისათვის განკუთვნილი ოდენობა | C28: 1 | D28: =D29*C28 -> 0
B29: საპენსიო ვალდებულებები | D29: =რეზერვები!J48 -> 0
B31: სიცოცხლის დაზღვევის რეზერვის ინვესტირებას დაქვემდებარებული ოდენობა | C31: 1 | D31: =(D32-D33)*C31 -> 0
B32: სადაზღვევო რეზერვი სიცოცხლის მაგროვებადი და დაბრუნებადი დაზღვევის სახეობებისათვის – სიცოცხლის დაზღვევის რეზერვი | D32: =რეზერვები!H48 -> 0
B33: გადამზღვევლის წილი | D33: =რეზერვები!H48-რეზერვები!I48 -> 0
B35: ინვესტირებას დაქვემდებარებული რეზერვების ჯამური ოდენობა | D35: =D31+D28+IF(D23+D15+IF(D7<0,0,D7)<0,0,D23+D15+IF(D7<0,0,D7)) -> 0
B38: =რეზერვები!B51 -> გენერალური დირექტორი (დირექტორი) _____________________________
B39: =რეზერვები!B52 -> (სახელი გვარი)
B42: =რეზერვები!B55 -> ანგარიშგებაზე პასუხისმგებელი პირი ________________________________________________________________
B43: =რეზერვები!B56 -> (სახელი გვარი, ტელეფონის ნომერი, ელ–ფოსტის მისამართი)

Sheet დასაშვები აქტივების სტრუქტურა
B1: ფორმა 13
B2: შეზღუდვები "ინვესტირებისათვის განკუთვნილი სადაზღვევო რეზერვების ჯამური ოდენობის" განთავსების მიმართ
B4: =რეზერვები!B4 -> კომპანიის დასახელება: ___________________________________
B5: =რეზერვები!B5 -> საანგარიშო თარიღი: ___________________________________
I6: ლარი
B7: № | C7: აქტივის კოდი | D7: ინვესტირებისათვის დასაშვები ოდენობა | F7: თითოეულ ობიექტში განხორციელებული ინვესტიციის დასაშვები ოდენობა | H7: ინვესტირებას დაქვემდებარებული მინიმალური ოდენობა
B8: 1 | C8: A1 | D8: 0.3 | E8: ='ინვ. დაქვ. რეზერვ. ოდენობა'!$D$35*D8 -> 0 | F8: 0.3 | G8: ='ინვ. დაქვ. რეზერვ. ოდენობა'!$D$35*F8 -> 0
B9: 2 | C9: A2 | D9: 0.3 | E9: ='ინვ. დაქვ. რეზერვ. ოდენობა'!$D$35*D9 -> 0 | F9: 0.3 | G9: ='ინვ. დაქვ. რეზერვ. ოდენობა'!$D$35*F9 -> 0
B10: 3 | C10: A1+A2 | D10: 0.5 | E10: ='ინვ. დაქვ. რეზერვ. ოდენობა'!$D$35*D10 -> 0
B11: 4 | C11: A3 | D11: 0.15 | E11: ='ინვ. დაქვ. რეზერვ. ოდენობა'!$D$35*D11 -> 0 | F11: 0.03 | G11: ='ინვ. დაქვ. რეზერვ. ოდენობა'!$D$35*F11 -> 0
B12: 5 | C12: A4 | D12: 0.1 | E12: ='ინვ. დაქვ. რეზერვ. ოდენობა'!$D$35*D12 -> 0 | F12: 0.025 | G12: ='ინვ. დაქვ. რეზერვ. ოდენობა'!$D$35*F12 -> 0
B13: 6 | C13: A5 | D13: 0.15 | E13: ='ინვ. დაქვ. რეზერვ. ოდენობა'!$D$35*D13 -> 0 | F13: 0.02 | G13: ='ინვ. დაქვ. რეზერვ. ოდენობა'!$D$35*F13 -> 0
B14: 7 | C14: A6 | D14: 0.1 | E14: ='ინვ. დაქვ. რეზერვ. ოდენობა'!$D$35*D14 -> 0 | F14: 0.01 | G14: ='ინვ. დაქვ. რეზერვ. ოდენობა'!$D$35*F14 -> 0
B15: 8 | C15: A3+A4+A5+A6 | D15: 0.15 | E15: ='ინვ. დაქვ. რეზერვ. ოდენობა'!$D$35*D15 -> 0
B16: 9 | C16: A7 | D16: 0.2 | E16: ='ინვ. დაქვ. რეზერვ. ოდენობა'!$D$35*D16 -> 0 | F16: 0.1 | G16: ='ინვ. დაქვ. რეზერვ. ოდენობა'!$D$35*F16 -> 0
B17: 10 | C17: A8 | D17: 0.2 | E17: ='ინვ. დაქვ. რეზერვ. ოდენობა'!$D$35*D17 -> 0 | F17: 0.1 | G17: ='ინვ. დაქვ. რეზერვ. ოდენობა'!$D$35*F17 -> 0
B18: 11 | C18: A9 | D18: 0.1 | E18: ='ინვ. დაქვ. რეზერვ. ოდენობა'!$D$35*D18 -> 0 | F18: 0.02 | G18: ='ინვ. დაქვ. რეზერვ. ოდენობა'!$D$35*F18 -> 0
B19: 12 | C19: A7+A8+A9 | D19: 0.2 | E19: ='ინვ. დაქვ. რეზერვ. ოდენობა'!$D$35*D19 -> 0
B20: 13 | C20: A10 | D20: 0.25 | E20: ='ინვ. დაქვ. რეზერვ. ოდენობა'!$D$35*D20 -> 0 | F20: 0.1 | G20: ='ინვ. დაქვ. რეზერვ. ოდენობა'!$D$35*F20 -> 0
B21: 14 | C21: A11 | D21: 0.9 | E21: ='ინვ. დაქვ. რეზერვ. ოდენობა'!$D$35*D21 -> 0 | F21: 0.3 | G21: ='ინვ. დაქვ. რეზერვ. ოდენობა'!$D$35*F21 -> 0
B22: 15 | C22: A12 (ფული სალაროში) | D22: 1 | E22: ='ინვ. დაქვ. რეზერვ. ოდენობა'!$D$35*D22 -> 0 | F22: 0.03 | G22: =IF('ინვ. დაქვ. რეზერვ. ოდენობა'!D35*F22>=100000,100000,'ინვ. დაქვ. რეზერვ. ოდენობა'!D35*F22) -> 0 | H22: 0.1 | I22: ='ინვ. დაქვ. რეზერვ. ოდენობა'!$D$35*'დასაშვები აქტივების სტრუქტურა'!H22 -> 0
B23: 16 | C23: A12 (საბანკო დაწესებულებები) | D23: 1 | E23: ='ინვ. დაქვ. რეზერვ. ოდენობა'!$D$35*D23 -> 0 | F23: 0.2 | G23: ='ინვ. დაქვ. რეზერვ. ოდენობა'!$D$35*F23 -> 0
B25: ='ინვ. დაქვ. რეზერვ. ოდენობა'!$B$38 -> გენერალური დირექტორი (დირექტორი) _____________________________
B26: =რეზერვები!B52 -> (სახელი გვარი)
B29: ='ინვ. დაქვ. რეზერვ. ოდენობა'!$B$42 -> ანგარიშგებაზე პასუხისმგებელი პირი ________________________________________________________________
B30: =რეზერვები!B56 -> (სახელი გვარი, ტელეფონის ნომერი, ელ–ფოსტის მისამართი) | C30: ='ინვ. დაქვ. რეზერვ. ოდენობა'!B43 -> (სახელი გვარი, ტელეფონის ნომერი, ელ–ფოსტის მისამართი)

Sheet A1
A1: ფორმა N 14.1
A2: A1 მიმართულებით განხორციელებული ინვესტიცია
A4: =რეზერვები!B4 -> კომპანიის დასახელება: ___________________________________
A5: =რეზერვები!B5 -> საანგარიშო თარიღი: ___________________________________
E6: ლარი
A7: A1 | B7: საქართველოს, "ეგთო"–ს წევრი ქვეყნებისა და/ან განვითარებული ქვეყნების ცენტრალური მთავრობების მიერ გამოშვებული სასესხო ფასიანი ქაღალდები | C7: ემიტენტის რეგისტრაციის ქვეყანა | D7: აქტივის საბალანსო ღირებულება საანგარიშო პერიოდის ბოლოს | E7: ინვესტირებისათვის დასაშვები ოდენობა
A8: 1 | B8: 2 | C8: 3 | D8: 4 | E8: 5
A9: 1 | B9: ემიტენტის დასახელება, ფასიანი ქაღალდის სახეობა | E9: =IF(D9>'დასაშვები აქტივების სტრუქტურა'!$G$8,'დასაშვები აქტივების სტრუქტურა'!$G$8,D9) -> 0
A10: 2 | B10: ემიტენტის დასახელება, ფასიანი ქაღალდის სახეობა | E10: =IF(D10>'დასაშვები აქტივების სტრუქტურა'!$G$8,'დასაშვები აქტივების სტრუქტურა'!$G$8,D10) -> 0
A11: 3 | B11: ემიტენტის დასახელება, ფასიანი ქაღალდის სახეობა | E11: =IF(D11>'დასაშვები აქტივების სტრუქტურა'!$G$8,'დასაშვები აქტივების სტრუქტურა'!$G$8,D11) -> 0
A12: 4 | B12: ემიტენტის დასახელება, ფასიანი ქაღალდის სახეობა | E12: =IF(D12>'დასაშვები აქტივების სტრუქტურა'!$G$8,'დასაშვები აქტივების სტრუქტურა'!$G$8,D12) -> 0
A13: 5 | B13: ემიტენტის დასახელება, ფასიანი ქაღალდის სახეობა | E13: =IF(D13>'დასაშვები აქტივების სტრუქტურა'!$G$8,'დასაშვები აქტივების სტრუქტურა'!$G$8,D13) -> 0
A14: 6 | B14: ემიტენტის დასახელება, ფასიანი ქაღალდის სახეობა | E14: =IF(D14>'დასაშვები აქტივების სტრუქტურა'!$G$8,'დასაშვები აქტივების სტრუქტურა'!$G$8,D14) -> 0
A15: 7 | B15: ემიტენტის დასახელება, ფასიანი ქაღალდის სახეობა | E15: =IF(D15>'დასაშვები აქტივების სტრუქტურა'!$G$8,'დასაშვები აქტივების სტრუქტურა'!$G$8,D15) -> 0
A16: 8 | B16: ემიტენტის დასახელება, ფასიანი ქაღალდის სახეობა | E16: =IF(D16>'დასაშვები აქტივების სტრუქტურა'!$G$8,'დასაშვები აქტივების სტრუქტურა'!$G$8,D16) -> 0
A17: 9 | B17: ემიტენტის დასახელება, ფასიანი ქაღალდის სახეობა | E17: =IF(D17>'დასაშვები აქტივების სტრუქტურა'!$G$8,'დასაშვები აქტივების სტრუქტურა'!$G$8,D17) -> 0
A18: 10 | B18: ემიტენტის დასახელება, ფასიანი ქაღალდის სახეობა | E18: =IF(D18>'დასაშვები აქტივების სტრუქტურა'!$G$8,'დასაშვები აქტივების სტრუქტურა'!$G$8,D18) -> 0
A19: 11 | B19: ემიტენტის დასახელება, ფასიანი ქაღალდის სახეობა | E19: =IF(D19>'დასაშვები აქტივების სტრუქტურა'!$G$8,'დასაშვები აქტივების სტრუქტურა'!$G$8,D19) -> 0
A20: 12 | B20: ემიტენტის დასახელება, ფასიანი ქაღალდის სახეობა | E20: =IF(D20>'დასაშვები აქტივების სტრუქტურა'!$G$8,'დასაშვები აქტივების სტრუქტურა'!$G$8,D20) -> 0
... A28: 20 | B28: ემიტენტის დასახელება, ფასიანი ქაღალდის სახეობა | E28: =IF(D28>'დასაშვები აქტივების სტრუქტურა'!$G$8,'დასაშვები აქტივების სტრუქტურა'!$G$8,D28) -> 0
B29: სულ | D29: =SUM(D9:D28) -> 0 | E29: =IF(SUM(E9:E28)>'დასაშვები აქტივების სტრუქტურა'!$E$8,'დასაშვები აქტივების სტრუქტურა'!$E$8,SUM(E9:E28)) -> 0
A31: შენიშვნა: ფორმაში მითითებული აქტივების მიმართ გამოყენებული არ უნდა იყოს საქართველოს კანონმდებლობით გათვალისწინებული უზრუნველყოფის საშუალებები (ყადაღა, იპოთეკა, გირავნობა და სხვა).
A33: ='ინვ. დაქვ. რეზერვ. ოდენობა'!$B$38 -> გენერალური დირექტორი (დირექტორი) _____________________________
A34: =რეზერვები!B52 -> (სახელი გვარი)
A37: ='ინვ. დაქვ. რეზერვ. ოდენობა'!$B$42 -> ანგარიშგებაზე პასუხისმგებელი პირი ________________________________________________________________
B38: ='ინვ. დაქვ. რეზერვ. ოდენობა'!B43 -> (სახელი გვარი, ტელეფონის ნომერი, ელ–ფოსტის მისამართი)

Sheet A2
A1: ფორმა N 14.2
A2: A2 მიმართულებით განხორციელებული ინვესტიცია
A4: =რეზერვები!B4 -> კომპანიის დასახელება: ___________________________________
A5: =რეზერვები!B5 -> საანგარიშო თარიღი: ___________________________________
E6: ლარი
A7: A2 | B7: "ეგთო"–ს წევრი ქვეყნებისა და/ან განვითარებული ქვეყნების ადგილობრივი თვითმმართველობის ერთეულების შესაბამისი ორგანოების მიერ გამოშვებული სასესხო ფასიანი ქაღალდები | C7: ემიტენტის რეგისტრაციის ქვეყანა | D7: აქტივის საბალანსო ღირებულება საანგარიშო პერიოდის ბოლოს | E7: ინვესტირებისათვის დასაშვები ოდენობა
A8: 1 | B8: 2 | C8: 3 | D8: 4 | E8: 5
A9: 1 | B9: ემიტენტის დასახელება, ფასიანი ქაღალდის სახეობა | E9: =IF(D9>'დასაშვები აქტივების სტრუქტურა'!$G$9,'დასაშვები აქტივების სტრუქტურა'!$G$9,D9) -> 0
A10: 2 | B10: ემიტენტის დასახელება, ფასიანი ქაღალდის სახეობა | E10: =IF(D10>'დასაშვები აქტივების სტრუქტურა'!$G$9,'დასაშვები აქტივების სტრუქტურა'!$G$9,D10) -> 0
A11: 3 | B11: ემიტენტის დასახელება, ფასიანი ქაღალდის სახეობა | E11: =IF(D11>'დასაშვები აქტივების სტრუქტურა'!$G$9,'დასაშვები აქტივების სტრუქტურა'!$G$9,D11) -> 0
A12: 4 | B12: ემიტენტის დასახელება, ფასიანი ქაღალდის სახეობა | E12: =IF(D12>'დასაშვები აქტივების სტრუქტურა'!$G$9,'დასაშვები აქტივების სტრუქტურა'!$G$9,D12) -> 0
A13: 5 | B13: ემიტენტის დასახელება, ფასიანი ქაღალდის სახეობა | E13: =IF(D13>'დასაშვები აქტივების სტრუქტურა'!$G$9,'დასაშვები აქტივების სტრუქტურა'!$G$9,D13) -> 0
A14: 6 | B14: ემიტენტის დასახელება, ფასიანი ქაღალდის სახეობა | E14: =IF(D14>'დასაშვები აქტივების სტრუქტურა'!$G$9,'დასაშვები აქტივების სტრუქტურა'!$G$9,D14) -> 0
A15: 7 | B15: ემიტენტის დასახელება, ფასიანი ქაღალდის სახეობა | E15: =IF(D15>'დასაშვები აქტივების სტრუქტურა'!$G$9,'დასაშვები აქტივების სტრუქტურა'!$G$9,D15) -> 0
A16: 8 | B16: ემიტენტის დასახელება, ფასიანი ქაღალდის სახეობა | E16: =IF(D16>'დასაშვები აქტივების სტრუქტურა'!$G$9,'დასაშვები აქტივების სტრუქტურა'!$G$9,D16) -> 0
A17: 9 | B17: ემიტენტის დასახელება, ფასიანი ქაღალდის სახეობა | E17: =IF(D17>'დასაშვები აქტივების სტრუქტურა'!$G$9,'დასაშვები აქტივების სტრუქტურა'!$G$9,D17) -> 0
A18: 10 | B18: ემიტენტის დასახელება, ფასიანი ქაღალდის სახეობა | E18: =IF(D18>'დასაშვები აქტივების სტრუქტურა'!$G$9,'დასაშვები აქტივების სტრუქტურა'!$G$9,D18) -> 0
A19: 11 | B19: ემიტენტის დასახელება, ფასიანი ქაღალდის სახეობა | E19: =IF(D19>'დასაშვები აქტივების სტრუქტურა'!$G$9,'დასაშვები აქტივების სტრუქტურა'!$G$9,D19) -> 0
A20: 12 | B20: ემიტენტის დასახელება, ფასიანი ქაღალდის სახეობა | E20: =IF(D20>'დასაშვები აქტივების სტრუქტურა'!$G$9,'დასაშვები აქტივების სტრუქტურა'!$G$9,D20) -> 0
... A28: 20 | B28: ემიტენტის დასახელება, ფასიანი ქაღალდის სახეობა | E28: =IF(D28>'დასაშვები აქტივების სტრუქტურა'!$G$9,'დასაშვები აქტივების სტრუქტურა'!$G$9,D28) -> 0
B29: სულ | D29: =SUM(D9:D28) -> 0 | E29: =IF(SUM(E9:E28)>'დასაშვები აქტივების სტრუქტურა'!$E$9,'დასაშვები აქტივების სტრუქტურა'!$E$9,SUM(E9:E28)) -> 0
A31: შენიშვნა: ფორმაში მითითებული აქტივების მიმართ გამოყენებული არ უნდა იყოს საქართველოს კანონმდებლობით გათვალისწინებული უზრუნველყოფის საშუალებები (ყადაღა, იპოთეკა, გირავნობა და სხვა).
A33: ='ინვ. დაქვ. რეზერვ. ოდენობა'!$B$38 -> გენერალური დირექტორი (დირექტორი) _____________________________
A34: =რეზერვები!B52 -> (სახელი გვარი)
A37: ='ინვ. დაქვ. რეზერვ. ოდენობა'!$B$42 -> ანგარიშგებაზე პასუხისმგებელი პირი ________________________________________________________________
B38: ='ინვ. დაქვ. რეზერვ. ოდენობა'!B43 -> (სახელი გვარი, ტელეფონის ნომერი, ელ–ფოსტის მისამართი)

Sheet A3
A1: ფორმა N 14.3
A2: A3 მიმართულებით განხორციელებული ინვესტიცია
A4: =რეზერვები!B4 -> კომპანიის დასახელება: ___________________________________
A5: =რეზერვები!B5 -> საანგარიშო თარიღი: ___________________________________
F6: ლარი
A7: A3 | B7: სასესხო ფასიანი ქაღალდები (ობლიგაციები) და პრივილეგირებული აქციები, რომელთა მიმოქცევა ხორციელდება საქართველოს, "ეგთო"–ს წევრი ქვეყნების და/ან განვითარებული ქვეყნების ფასიანი ქაღალდების ორგანიზებულ ბაზარზე | C7: ემიტენტის რეგისტრაციის ქვეყანა | D7: ბირჟის დასახელება, რეგისტრაციის ქვეყანა | E7: აქტივის საბალანსო ღირებულება საანგარიშო პერიოდის ბოლოს | F7: ინვესტირებისათვის დასაშვები ოდენობა
A8: 1 | B8: 2 | C8: 3 | D8: 4 | E8: 5 | F8: 6
A9: 1 | B9: ემიტენტის დასახელება, ფასიანი ქაღალდის სახეობა | F9: =IF(E9>'დასაშვები აქტივების სტრუქტურა'!$G$11,'დასაშვები აქტივების სტრუქტურა'!$G$11,E9) -> 0
A10: 2 | B10: ემიტენტის დასახელება, ფასიანი ქაღალდის სახეობა | F10: =IF(E10>'დასაშვები აქტივების სტრუქტურა'!$G$11,'დასაშვები აქტივების სტრუქტურა'!$G$11,E10) -> 0
A11: 3 | B11: ემიტენტის დასახელება, ფასიანი ქაღალდის სახეობა | F11: =IF(E11>'დასაშვები აქტივების სტრუქტურა'!$G$11,'დასაშვები აქტივების სტრუქტურა'!$G$11,E11) -> 0
A12: 4 | B12: ემიტენტის დასახელება, ფასიანი ქაღალდის სახეობა | F12: =IF(E12>'დასაშვები აქტივების სტრუქტურა'!$G$11,'დასაშვები აქტივების სტრუქტურა'!$G$11,E12) -> 0
A13: 5 | B13: ემიტენტის დასახელება, ფასიანი ქაღალდის სახეობა | F13: =IF(E13>'დასაშვები აქტივების სტრუქტურა'!$G$11,'დასაშვები აქტივების სტრუქტურა'!$G$11,E13) -> 0
A14: 6 | B14: ემიტენტის დასახელება, ფასიანი ქაღალდის სახეობა | F14: =IF(E14>'დასაშვები აქტივების სტრუქტურა'!$G$11,'დასაშვები აქტივების სტრუქტურა'!$G$11,E14) -> 0
A15: 7 | B15: ემიტენტის დასახელება, ფასიანი ქაღალდის სახეობა | F15: =IF(E15>'დასაშვები აქტივების სტრუქტურა'!$G$11,'დასაშვები აქტივების სტრუქტურა'!$G$11,E15) -> 0
A16: 8 | B16: ემიტენტის დასახელება, ფასიანი ქაღალდის სახეობა | F16: =IF(E16>'დასაშვები აქტივების სტრუქტურა'!$G$11,'დასაშვები აქტივების სტრუქტურა'!$G$11,E16) -> 0
A17: 9 | B17: ემიტენტის დასახელება, ფასიანი ქაღალდის სახეობა | F17: =IF(E17>'დასაშვები აქტივების სტრუქტურა'!$G$11,'დასაშვები აქტივების სტრუქტურა'!$G$11,E17) -> 0
A18: 10 | B18: ემიტენტის დასახელება, ფასიანი ქაღალდის სახეობა | F18: =IF(E18>'დასაშვები აქტივების სტრუქტურა'!$G$11,'დასაშვები აქტივების სტრუქტურა'!$G$11,E18) -> 0
A19: 11 | B19: ემიტენტის დასახელება, ფასიანი ქაღალდის სახეობა | F19: =IF(E19>'დასაშვები აქტივების სტრუქტურა'!$G$11,'დასაშვები აქტივების სტრუქტურა'!$G$11,E19) -> 0
A20: 12 | B20: ემიტენტის დასახელება, ფასიანი ქაღალდის სახეობა | F20: =IF(E20>'დასაშვები აქტივების სტრუქტურა'!$G$11,'დასაშვები აქტივების სტრუქტურა'!$G$11,E20) -> 0
... A28: 20 | B28: ემიტენტის დასახელება, ფასიანი ქაღალდის სახეობა | F28: =IF(E28>'დასაშვები აქტივების სტრუქტურა'!$G$11,'დასაშვები აქტივების სტრუქტურა'!$G$11,E28) -> 0
B29: სულ | E29: =SUM(E9:E28) -> 0 | F29: =IF(SUM(F9:F28)>'დასაშვები აქტივების სტრუქტურა'!$E$11,'დასაშვები აქტივების სტრუქტურა'!$E$11,SUM(F9:F28)) -> 0
A31: შენიშვნა: ფასიანი ქაღალდები არ უნდა იყოს გამოშვებული მზღვეველთან დაკავშირებული პირების მიერ, თუ მზღვეველის მონაწილეობა დაკავშირებული პირების კაპიტალში აღემატება 20%–ს, ან თუ დაკავშირებული პირების მონაწილეობა მზღვეველის კაპიტალში აღემატება 20%–ს;
A32: შენიშვნა: ფორმაში მითითებული აქტივების მიმართ გამოყენებული არ უნდა იყოს საქართველოს კანონმდებლობით გათვალისწინებული უზრუნველყოფის საშუალებები (ყადაღა, იპოთეკა, გირავნობა და სხვა).
A34: ='ინვ. დაქვ. რეზერვ. ოდენობა'!$B$38 -> გენერალური დირექტორი (დირექტორი) _____________________________
A35: =რეზერვები!B52 -> (სახელი გვარი)
A38: ='ინვ. დაქვ. რეზერვ. ოდენობა'!$B$42 -> ანგარიშგებაზე პასუხისმგებელი პირი ________________________________________________________________
B39: ='ინვ. დაქვ. რეზერვ. ოდენობა'!$B$43 -> (სახელი გვარი, ტელეფონის ნომერი, ელ–ფოსტის მისამართი)

Sheet A4
A1: ფორმა N 14.4
A2: A4 მიმართულებით განხორციელებული ინვესტიცია
A4: =რეზერვები!B4 -> კომპანიის დასახელება: ___________________________________
A5: =რეზერვები!B5 -> საანგარიშო თარიღი: ___________________________________
E6: ლარი
A7: A4 | B7: საქართველოში, “ეგთო”–ს წევრ ქვეყნებში და/ან განვითარებულ ქვეყნებში რეგისტრირებული იურიდიული პირების მიერ გამოშვებული სასესხო ფასიანი ქაღალდები (ობლიგაციები) და პრივილეგირებული აქციები, რომელთა მიმოქცევა ხორციელდება ფასიანი ქაღალდების ორგანიზებული ბაზრის გარეთ | C7: ემიტენტის რეგისტრაციის ქვეყანა | D7: აქტივის საბალანსო ღირებულება საანგარიშო პერიოდის ბოლოს | E7: ინვესტირებისათვის დასაშვები ოდენობა
A8: 1 | B8: 2 | C8: 3 | D8: 4 | E8: 5
A9: 1 | B9: ემიტენტის დასახელება, ფასიანი ქაღალდის სახეობა | E9: =IF(D9>'დასაშვები აქტივების სტრუქტურა'!$G$12,'დასაშვები აქტივების სტრუქტურა'!$G$12,D9) -> 0
A10: 2 | B10: ემიტენტის დასახელება, ფასიანი ქაღალდის სახეობა | E10: =IF(D10>'დასაშვები აქტივების სტრუქტურა'!$G$12,'დასაშვები აქტივების სტრუქტურა'!$G$12,D10) -> 0
A11: 3 | B11: ემიტენტის დასახელება, ფასიანი ქაღალდის სახეობა | E11: =IF(D11>'დასაშვები აქტივების სტრუქტურა'!$G$12,'დასაშვები აქტივების სტრუქტურა'!$G$12,D11) -> 0
A12: 4 | B12: ემიტენტის დასახელება, ფასიანი ქაღალდის სახეობა | E12: =IF(D12>'დასაშვები აქტივების სტრუქტურა'!$G$12,'დასაშვები აქტივების სტრუქტურა'!$G$12,D12) -> 0
A13: 5 | B13: ემიტენტის დასახელება, ფასიანი ქაღალდის სახეობა | E13: =IF(D13>'დასაშვები აქტივების სტრუქტურა'!$G$12,'დასაშვები აქტივების სტრუქტურა'!$G$12,D13) -> 0
A14: 6 | B14: ემიტენტის დასახელება, ფასიანი ქაღალდის სახეობა | E14: =IF(D14>'დასაშვები აქტივების სტრუქტურა'!$G$12,'დასაშვები აქტივების სტრუქტურა'!$G$12,D14) -> 0
A15: 7 | B15: ემიტენტის დასახელება, ფასიანი ქაღალდის სახეობა | E15: =IF(D15>'დასაშვები აქტივების სტრუქტურა'!$G$12,'დასაშვები აქტივების სტრუქტურა'!$G$12,D15) -> 0
A16: 8 | B16: ემიტენტის დასახელება, ფასიანი ქაღალდის სახეობა | E16: =IF(D16>'დასაშვები აქტივების სტრუქტურა'!$G$12,'დასაშვები აქტივების სტრუქტურა'!$G$12,D16) -> 0
A17: 9 | B17: ემიტენტის დასახელება, ფასიანი ქაღალდის სახეობა | E17: =IF(D17>'დასაშვები აქტივების სტრუქტურა'!$G$12,'დასაშვები აქტივების სტრუქტურა'!$G$12,D17) -> 0
A18: 10 | B18: ემიტენტის დასახელება, ფასიანი ქაღალდის სახეობა | E18: =IF(D18>'დასაშვები აქტივების სტრუქტურა'!$G$12,'დასაშვები აქტივების სტრუქტურა'!$G$12,D18) -> 0
A19: 11 | B19: ემიტენტის დასახელება, ფასიანი ქაღალდის სახეობა | E19: =IF(D19>'დასაშვები აქტივების სტრუქტურა'!$G$12,'დასაშვები აქტივების სტრუქტურა'!$G$12,D19) -> 0
A20: 12 | B20: ემიტენტის დასახელება, ფასიანი ქაღალდის სახეობა | E20: =IF(D20>'დასაშვები აქტივების სტრუქტურა'!$G$12,'დასაშვები აქტივების სტრუქტურა'!$G$12,D20) -> 0
... A28: 20 | B28: ემიტენტის დასახელება, ფასიანი ქაღალდის სახეობა | E28: =IF(D28>'დასაშვები აქტივების სტრუქტურა'!$G$12,'დასაშვები აქტივების სტრუქტურა'!$G$12,D28) -> 0
B29: სულ | D29: =SUM(D9:D28) -> 0 | E29: =IF(SUM(E9:E28)>'დასაშვები აქტივების სტრუქტურა'!$E$12,'დასაშვები აქტივების სტრუქტურა'!$E$12,SUM(E9:E28)) -> 0
A31: შენიშვნა: ფასიანი ქაღალდები არ უნდა იყოს გამოშვებული მზღვეველთან დაკავშირებული პირების მიერ, თუ მზღვეველის მონაწილეობა დაკავშირებული პირების კაპიტალში აღემატება 20%–ს, ან თუ დაკავშირებული პირების მონაწილეობა მზღვეველის კაპიტალში აღემატება 20%–ს;
A32: შენიშვნა: ფორმაში მითითებული აქტივების მიმართ გამოყენებული არ უნდა იყოს საქართველოს კანონმდებლობით გათვალისწინებული უზრუნველყოფის საშუალებები (ყადაღა, იპოთეკა, გირავნობა და სხვა).
A34: ='ინვ. დაქვ. რეზერვ. ოდენობა'!$B$38 -> გენერალური დირექტორი (დირექტორი) _____________________________
A35: =რეზერვები!B52 -> (სახელი გვარი)
A38: ='ინვ. დაქვ. რეზერვ. ოდენობა'!$B$42 -> ანგარიშგებაზე პასუხისმგებელი პირი ________________________________________________________________
B39: ='ინვ. დაქვ. რეზერვ. ოდენობა'!$B$43 -> (სახელი გვარი, ტელეფონის ნომერი, ელ–ფოსტის მისამართი)

Sheet A5
A1: ფორმა N 14.5
A2: A5 მიმართულებით განხორციელებული ინვესტიცია
A4: =რეზერვები!B4 -> კომპანიის დასახელება: ___________________________________
A5: =რეზერვები!B5 -> საანგარიშო თარიღი: ___________________________________
F6: ლარი
A7: A5 | B7: წილობრივი ფასიანი ქაღალდები (გარდა პრივილეგირებული აქციებისა), რომელთა მიმოქცევა ხორციელდება საქართველოს, “ეგთო”–ს წევრი ქვეყნების და/ან განვითარებული ქვეყნების ფასიანი ქაღალდების ორგანიზებულ ბაზარზე | C7: ემიტენტის რეგისტრაციის ქვეყანა | D7: ბირჟის დასახელება, რეგისტრაციის ქვეყანა | E7: აქტივის საბალანსო ღირებულება საანგარიშო პერიოდის ბოლოს | F7: ინვესტირებისათვის დასაშვები ოდენობა
A8: 1 | B8: 2 | C8: 3 | D8: 4 | E8: 5 | F8: 6
A9: 1 | B9: ემიტენტის დასახელება, ფასიანი ქაღალდის სახეობა | F9: =IF(E9>'დასაშვები აქტივების სტრუქტურა'!$G$13,'დასაშვები აქტივების სტრუქტურა'!$G$13,E9) -> 0
A10: 2 | B10: ემიტენტის დასახელება, ფასიანი ქაღალდის სახეობა | F10: =IF(E10>'დასაშვები აქტივების სტრუქტურა'!$G$13,'დასაშვები აქტივების სტრუქტურა'!$G$13,E10) -> 0
A11: 3 | B11: ემიტენტის დასახელება, ფასიანი ქაღალდის სახეობა | F11: =IF(E11>'დასაშვები აქტივების სტრუქტურა'!$G$13,'დასაშვები აქტივების სტრუქტურა'!$G$13,E11) -> 0
A12: 4 | B12: ემიტენტის დასახელება, ფასიანი ქაღალდის სახეობა | F12: =IF(E12>'დასაშვები აქტივების სტრუქტურა'!$G$13,'დასაშვები აქტივების სტრუქტურა'!$G$13,E12) -> 0
A13: 5 | B13: ემიტენტის დასახელება, ფასიანი ქაღალდის სახეობა | F13: =IF(E13>'დასაშვები აქტივების სტრუქტურა'!$G$13,'დასაშვები აქტივების სტრუქტურა'!$G$13,E13) -> 0
A14: 6 | B14: ემიტენტის დასახელება, ფასიანი ქაღალდის სახეობა | F14: =IF(E14>'დასაშვები აქტივების სტრუქტურა'!$G$13,'დასაშვები აქტივების სტრუქტურა'!$G$13,E14) -> 0
A15: 7 | B15: ემიტენტის დასახელება, ფასიანი ქაღალდის სახეობა | F15: =IF(E15>'დასაშვები აქტივების სტრუქტურა'!$G$13,'დასაშვები აქტივების სტრუქტურა'!$G$13,E15) -> 0
A16: 8 | B16: ემიტენტის დასახელება, ფასიანი ქაღალდის სახეობა | F16: =IF(E16>'დასაშვები აქტივების სტრუქტურა'!$G$13,'დასაშვები აქტივების სტრუქტურა'!$G$13,E16) -> 0
A17: 9 | B17: ემიტენტის დასახელება, ფასიანი ქაღალდის სახეობა | F17: =IF(E17>'დასაშვები აქტივების სტრუქტურა'!$G$13,'დასაშვები აქტივების სტრუქტურა'!$G$13,E17) -> 0
A18: 10 | B18: ემიტენტის დასახელება, ფასიანი ქაღალდის სახეობა | F18: =IF(E18>'დასაშვები აქტივების სტრუქტურა'!$G$13,'დასაშვები აქტივების სტრუქტურა'!$G$13,E18) -> 0
A19: 11 | B19: ემიტენტის დასახელება, ფასიანი ქაღალდის სახეობა | F19: =IF(E19>'დასაშვები აქტივების სტრუქტურა'!$G$13,'დასაშვები აქტივების სტრუქტურა'!$G$13,E19) -> 0
A20: 12 | B20: ემიტენტის დასახელება, ფასიანი ქაღალდის სახეობა | F20: =IF(E20>'დასაშვები აქტივების სტრუქტურა'!$G$13,'დასაშვები აქტივების სტრუქტურა'!$G$13,E20) -> 0
... A28: 20 | B28: ემიტენტის დასახელება, ფასიანი ქაღალდის სახეობა | F28: =IF(E28>'დასაშვები აქტივების სტრუქტურა'!$G$13,'დასაშვები აქტივების სტრუქტურა'!$G$13,E28) -> 0
B29: სულ | E29: =SUM(E9:E28) -> 0 | F29: =IF(SUM(F9:F28)>'დასაშვები აქტივების სტრუქტურა'!$E$13,'დასაშვები აქტივების სტრუქტურა'!$E$13,SUM(F9:F28)) -> 0
A31: შენიშვნა: ფასიანი ქაღალდები არ უნდა იყოს გამოშვებული მზღვეველთან დაკავშირებული პირების მიერ, თუ მზღვეველის მონაწილეობა დაკავშირებული პირების კაპიტალში აღემატება 20%–ს, ან თუ დაკავშირებული პირების მონაწილეობა მზღვეველის კაპიტალში აღემატება 20%–ს;
A32: შენიშვნა: ფორმაში მითითებული აქტივების მიმართ გამოყენებული არ უნდა იყოს საქართველოს კანონმდებლობით გათვალისწინებული უზრუნველყოფის საშუალებები (ყადაღა, იპოთეკა, გირავნობა და სხვა).
A34: ='ინვ. დაქვ. რეზერვ. ოდენობა'!$B$38 -> გენერალური დირექტორი (დირექტორი) _____________________________
A35: =რეზერვები!B52 -> (სახელი გვარი)
A38: ='ინვ. დაქვ. რეზერვ. ოდენობა'!$B$42 -> ანგარიშგებაზე პასუხისმგებელი პირი ________________________________________________________________
B39: ='ინვ. დაქვ. რეზერვ. ოდენობა'!$B$43 -> (სახელი გვარი, ტელეფონის ნომერი, ელ–ფოსტის მისამართი)

Sheet A6
A1: ფორმა N 14.6
A2: A6 მიმართულებით განხორციელებული ინვესტიცია
A4: =რეზერვები!B4 -> კომპანიის დასახელება: ___________________________________
A5: =რეზერვები!B5 -> საანგარიშო თარიღი: ___________________________________
E6: ლარი
A7: A6 | B7: საქართველოში, “ეგთო”–ს წევრ ქვეყნებში და/ან განვითარებულ ქვეყნებში რეგისტრირებული იურიდიული პირების მიერ გამოშვებული წილობრივი ფასიანი ქაღალდები (გარდა პრივილეგირებული აქციებისა), რომელთა მიმოქცევა ხორციელდება ფასიანი ქაღალდების ორგანიზებული ბაზრის გარეთ | C7: ემიტენტის რეგისტრაციის ქვეყანა | D7: აქტივის საბალანსო ღირებულება საანგარიშო პერიოდის ბოლოს | E7: ინვესტირებისათვის დასაშვები ოდენობა
A8: 1 | B8: 2 | C8: 3 | D8: 4 | E8: 5
A9: 1 | B9: ემიტენტის დასახელება, ფასიანი ქაღალდის სახეობა | E9: =IF(D9>'დასაშვები აქტივების სტრუქტურა'!$G$14,'დასაშვები აქტივების სტრუქტურა'!$G$14,D9) -> 0
A10: 2 | B10: ემიტენტის დასახელება, ფასიანი ქაღალდის სახეობა | E10: =IF(D10>'დასაშვები აქტივების სტრუქტურა'!$G$14,'დასაშვები აქტივების სტრუქტურა'!$G$14,D10) -> 0
A11: 3 | B11: ემიტენტის დასახელება, ფასიანი ქაღალდის სახეობა | E11: =IF(D11>'დასაშვები აქტივების სტრუქტურა'!$G$14,'დასაშვები აქტივების სტრუქტურა'!$G$14,D11) -> 0
A12: 4 | B12: ემიტენტის დასახელება, ფასიანი ქაღალდის სახეობა | E12: =IF(D12>'დასაშვები აქტივების სტრუქტურა'!$G$14,'დასაშვები აქტივების სტრუქტურა'!$G$14,D12) -> 0
A13: 5 | B13: ემიტენტის დასახელება, ფასიანი ქაღალდის სახეობა | E13: =IF(D13>'დასაშვები აქტივების სტრუქტურა'!$G$14,'დასაშვები აქტივების სტრუქტურა'!$G$14,D13) -> 0
A14: 6 | B14: ემიტენტის დასახელება, ფასიანი ქაღალდის სახეობა | E14: =IF(D14>'დასაშვები აქტივების სტრუქტურა'!$G$14,'დასაშვები აქტივების სტრუქტურა'!$G$14,D14) -> 0
A15: 7 | B15: ემიტენტის დასახელება, ფასიანი ქაღალდის სახეობა | E15: =IF(D15>'დასაშვები აქტივების სტრუქტურა'!$G$14,'დასაშვები აქტივების სტრუქტურა'!$G$14,D15) -> 0
A16: 8 | B16: ემიტენტის დასახელება, ფასიანი ქაღალდის სახეობა | E16: =IF(D16>'დასაშვები აქტივების სტრუქტურა'!$G$14,'დასაშვები აქტივების სტრუქტურა'!$G$14,D16) -> 0
A17: 9 | B17: ემიტენტის დასახელება, ფასიანი ქაღალდის სახეობა | E17: =IF(D17>'დასაშვები აქტივების სტრუქტურა'!$G$14,'დასაშვები აქტივების სტრუქტურა'!$G$14,D17) -> 0
A18: 10 | B18: ემიტენტის დასახელება, ფასიანი ქაღალდის სახეობა | E18: =IF(D18>'დასაშვები აქტივების სტრუქტურა'!$G$14,'დასაშვები აქტივების სტრუქტურა'!$G$14,D18) -> 0
A19: 11 | B19: ემიტენტის დასახელება, ფასიანი ქაღალდის სახეობა | E19: =IF(D19>'დასაშვები აქტივების სტრუქტურა'!$G$14,'დასაშვები აქტივების სტრუქტურა'!$G$14,D19) -> 0
A20: 12 | B20: ემიტენტის დასახელება, ფასიანი ქაღალდის სახეობა | E20: =IF(D20>'დასაშვები აქტივების სტრუქტურა'!$G$14,'დასაშვები აქტივების სტრუქტურა'!$G$14,D20) -> 0
... A28: 20 | B28: ემიტენტის დასახელება, ფასიანი ქაღალდის სახეობა | E28: =IF(D28>'დასაშვები აქტივების სტრუქტურა'!$G$14,'დასაშვები აქტივების სტრუქტურა'!$G$14,D28) -> 0
B29: სულ | D29: =SUM(D9:D28) -> 0 | E29: =IF(SUM(E9:E28)>'დასაშვები აქტივების სტრუქტურა'!$E$14,'დასაშვები აქტივების სტრუქტურა'!$E$14,SUM(E9:E28)) -> 0
A31: შენიშვნა: ფასიანი ქაღალდები არ უნდა იყოს გამოშვებული მზღვეველთან დაკავშირებული პირების მიერ, თუ მზღვეველის მონაწილეობა დაკავშირებული პირების კაპიტალში აღემატება 20%–ს, ან თუ დაკავშირებული პირების მონაწილეობა მზღვეველის კაპიტალში აღემატება 20%–ს;
A32: შენიშვნა: ფორმაში მითითებული აქტივების მიმართ გამოყენებული არ უნდა იყოს საქართველოს კანონმდებლობით გათვალისწინებული უზრუნველყოფის საშუალებები (ყადაღა, იპოთეკა, გირავნობა და სხვა).
A34: ='ინვ. დაქვ. რეზერვ. ოდენობა'!$B$38 -> გენერალური დირექტორი (დირექტორი) _____________________________
A35: =რეზერვები!B52 -> (სახელი გვარი)
A38: ='ინვ. დაქვ. რეზერვ. ოდენობა'!$B$42 -> ანგარიშგებაზე პასუხისმგებელი პირი ________________________________________________________________
B39: ='ინვ. დაქვ. რეზერვ. ოდენობა'!$B$43 -> (სახელი გვარი, ტელეფონის ნომერი, ელ–ფოსტის მისამართი)

Sheet A7
A1: ფორმა N 14.7
A2: A7 მიმართულებით განხორციელებული ინვესტიცია
A4: =რეზერვები!B4 -> კომპანიის დასახელება: ___________________________________
A5: =რეზერვები!B5 -> საანგარიშო თარიღი: ___________________________________
E6: ლარი
A7: A7 | B7: საქართველოში, “ეგთო”–ს წევრ ქვეყნებში და/ან განვითარებულ ქვეყნებში რეგისტრირებული ქონების უზრუნველყოფით გაცემული იპოთეკური სესხები | C7: უზრუნველყოფის საგანი, მისი ადგილმდებარეობა და რეგისტრაციის ქვეყანა | D7: აქტივის საბალანსო ღირებულება საანგარიშო პერიოდის ბოლოს | E7: ინვესტირებისათვის დასაშვები ოდენობა
A8: 1 | B8: 2 | C8: 3 | D8: 4 | E8: 5
A9: 1 | B9: მსესხებლის დასახელება, რეგისტრაციის ქვეყანა | E9: =IF(D9>'დასაშვები აქტივების სტრუქტურა'!$G$16,'დასაშვები აქტივების სტრუქტურა'!$G$16,D9) -> 0
A10: 2 | B10: მსესხებლის დასახელება, რეგისტრაციის ქვეყანა | E10: =IF(D10>'დასაშვები აქტივების სტრუქტურა'!$G$16,'დასაშვები აქტივების სტრუქტურა'!$G$16,D10) -> 0
A11: 3 | B11: მსესხებლის დასახელება, რეგისტრაციის ქვეყანა | E11: =IF(D11>'დასაშვები აქტივების სტრუქტურა'!$G$16,'დასაშვები აქტივების სტრუქტურა'!$G$16,D11) -> 0
A12: 4 | B12: მსესხებლის დასახელება, რეგისტრაციის ქვეყანა | E12: =IF(D12>'დასაშვები აქტივების სტრუქტურა'!$G$16,'დასაშვები აქტივების სტრუქტურა'!$G$16,D12) -> 0
A13: 5 | B13: მსესხებლის დასახელება, რეგისტრაციის ქვეყანა | E13: =IF(D13>'დასაშვები აქტივების სტრუქტურა'!$G$16,'დასაშვები აქტივების სტრუქტურა'!$G$16,D13) -> 0
A14: 6 | B14: მსესხებლის დასახელება, რეგისტრაციის ქვეყანა | E14: =IF(D14>'დასაშვები აქტივების სტრუქტურა'!$G$16,'დასაშვები აქტივების სტრუქტურა'!$G$16,D14) -> 0
A15: 7 | B15: მსესხებლის დასახელება, რეგისტრაციის ქვეყანა | E15: =IF(D15>'დასაშვები აქტივების სტრუქტურა'!$G$16,'დასაშვები აქტივების სტრუქტურა'!$G$16,D15) -> 0
A16: 8 | B16: მსესხებლის დასახელება, რეგისტრაციის ქვეყანა | E16: =IF(D16>'დასაშვები აქტივების სტრუქტურა'!$G$16,'დასაშვები აქტივების სტრუქტურა'!$G$16,D16) -> 0
A17: 9 | B17: მსესხებლის დასახელება, რეგისტრაციის ქვეყანა | E17: =IF(D17>'დასაშვები აქტივების სტრუქტურა'!$G$16,'დასაშვები აქტივების სტრუქტურა'!$G$16,D17) -> 0
A18: 10 | B18: მსესხებლის დასახელება, რეგისტრაციის ქვეყანა | E18: =IF(D18>'დასაშვები აქტივების სტრუქტურა'!$G$16,'დასაშვები აქტივების სტრუქტურა'!$G$16,D18) -> 0
A19: 11 | B19: მსესხებლის დასახელება, რეგისტრაციის ქვეყანა | E19: =IF(D19>'დასაშვები აქტივების სტრუქტურა'!$G$16,'დასაშვები აქტივების სტრუქტურა'!$G$16,D19) -> 0
A20: 12 | B20: მსესხებლის დასახელება, რეგისტრაციის ქვეყანა | E20: =IF(D20>'დასაშვები აქტივების სტრუქტურა'!$G$16,'დასაშვები აქტივების სტრუქტურა'!$G$16,D20) -> 0
... A28: 20 | B28: მსესხებლის დასახელება, რეგისტრაციის ქვეყანა | E28: =IF(D28>'დასაშვები აქტივების სტრუქტურა'!$G$16,'დასაშვები აქტივების სტრუქტურა'!$G$16,D28) -> 0
B29: სულ | D29: =SUM(D9:D28) -> 0 | E29: =IF(SUM(E9:E28)>'დასაშვები აქტივების სტრუქტურა'!$E$16,'დასაშვები აქტივების სტრუქტურა'!$E$16,SUM(E9:E28)) -> 0
A31: შენიშვნა: ფორმაში მითითებული სესხები არ უნდა იყოს გაცემული მზღვეველთან დაკავშირებულ პირებზე, თუ მზღვეველის მონაწილეობა დაკავშირებული პირების კაპიტალში აღემატება 20%–ს, ან თუ დაკავშირებული პირების მონაწილეობა მზღვეველის კაპიტალში აღემატება 20%–ს.
A33: ='ინვ. დაქვ. რეზერვ. ოდენობა'!$B$38 -> გენერალური დირექტორი (დირექტორი) _____________________________
A34: =რეზერვები!B52 -> (სახელი გვარი)
A37: ='ინვ. დაქვ. რეზერვ. ოდენობა'!$B$42 -> ანგარიშგებაზე პასუხისმგებელი პირი ________________________________________________________________
B38: ='ინვ. დაქვ. რეზერვ. ოდენობა'!$B$43 -> (სახელი გვარი, ტელეფონის ნომერი, ელ–ფოსტის მისამართი)

Sheet A8
A1: ფორმა N 14.8
A2: A8 მიმართულებით განხორციელებული ინვესტიცია
A4: =რეზერვები!B4 -> კომპანიის დასახელება: ___________________________________
A5: =რეზერვები!B5 -> საანგარიშო თარიღი: ___________________________________
E6: ლარი
A7: A8 | B7: საქართველოს, "ეგთო"–ს წევრ ქვეყნებისა და/ან განვითარებული ქვეყნების შესაბამისი უფლებამოსილების მქონე ორგანოს მიერ ლიცენზირებული საბანკო დაწესებულებებისათვის გაცემული სესხები | C7: ბანკის რეგისტრაციის ქვეყანა | D7: აქტივის საბალანსო ღირებულება საანგარიშო პერიოდის ბოლოს | E7: ინვესტირებისათვის დასაშვები ოდენობა
A8: 1 | B8: 2 | C8: 3 | D8: 4 | E8: 5
A9: 1 | B9: მსესხებელი ბანკის დასახელება | E9: =IF(D9>'დასაშვები აქტივების სტრუქტურა'!$G$17,'დასაშვები აქტივების სტრუქტურა'!$G$17,D9) -> 0
A10: 2 | B10: მსესხებელი ბანკის დასახელება | E10: =IF(D10>'დასაშვები აქტივების სტრუქტურა'!$G$17,'დასაშვები აქტივების სტრუქტურა'!$G$17,D10) -> 0
A11: 3 | B11: მსესხებელი ბანკის დასახელება | E11: =IF(D11>'დასაშვები აქტივების სტრუქტურა'!$G$17,'დასაშვები აქტივების სტრუქტურა'!$G$17,D11) -> 0
A12: 4 | B12: მსესხებელი ბანკის დასახელება | E12: =IF(D12>'დასაშვები აქტივების სტრუქტურა'!$G$17,'დასაშვები აქტივების სტრუქტურა'!$G$17,D12) -> 0
A13: 5 | B13: მსესხებელი ბანკის დასახელება | E13: =IF(D13>'დასაშვები აქტივების სტრუქტურა'!$G$17,'დასაშვები აქტივების სტრუქტურა'!$G$17,D13) -> 0
A14: 6 | B14: მსესხებელი ბანკის დასახელება | E14: =IF(D14>'დასაშვები აქტივების სტრუქტურა'!$G$17,'დასაშვები აქტივების სტრუქტურა'!$G$17,D14) -> 0
A15: 7 | B15: მსესხებელი ბანკის დასახელება | E15: =IF(D15>'დასაშვები აქტივების სტრუქტურა'!$G$17,'დასაშვები აქტივების სტრუქტურა'!$G$17,D15) -> 0
A16: 8 | B16: მსესხებელი ბანკის დასახელება | E16: =IF(D16>'დასაშვები აქტივების სტრუქტურა'!$G$17,'დასაშვები აქტივების სტრუქტურა'!$G$17,D16) -> 0
A17: 9 | B17: მსესხებელი ბანკის დასახელება | E17: =IF(D17>'დასაშვები აქტივების სტრუქტურა'!$G$17,'დასაშვები აქტივების სტრუქტურა'!$G$17,D17) -> 0
A18: 10 | B18: მსესხებელი ბანკის დასახელება | E18: =IF(D18>'დასაშვები აქტივების სტრუქტურა'!$G$17,'დასაშვები აქტივების სტრუქტურა'!$G$17,D18) -> 0
A19: 11 | B19: მსესხებელი ბანკის დასახელება | E19: =IF(D19>'დასაშვები აქტივების სტრუქტურა'!$G$17,'დასაშვები აქტივების სტრუქტურა'!$G$17,D19) -> 0
A20: 12 | B20: მსესხებელი ბანკის დასახელება | E20: =IF(D20>'დასაშვები აქტივების სტრუქტურა'!$G$17,'დასაშვები აქტივების სტრუქტურა'!$G$17,D20) -> 0
... A28: 20 | B28: მსესხებელი ბანკის დასახელება | E28: =IF(D28>'დასაშვები აქტივების სტრუქტურა'!$G$17,'დასაშვები აქტივების სტრუქტურა'!$G$17,D28) -> 0
B29: სულ | D29: =SUM(D9:D28) -> 0 | E29: =IF(SUM(E9:E28)>'დასაშვები აქტივების სტრუქტურა'!$E$17,'დასაშვები აქტივების სტრუქტურა'!$E$17,SUM(E9:E28)) -> 0
A31: შენიშვნა: ფორმაში მითითებული სესხები არ უნდა იყოს გაცემული მზღვეველთან დაკავშირებულ პირებზე, თუ მზღვეველის მონაწილეობა დაკავშირებული პირების კაპიტალში აღემატება 20%–ს, ან თუ დაკავშირებული პირების მონაწილეობა მზღვეველის კაპიტალში აღემატება 20%–ს.
A33: ='ინვ. დაქვ. რეზერვ. ოდენობა'!$B$38 -> გენერალური დირექტორი (დირექტორი) _____________________________
A34: =რეზერვები!B52 -> (სახელი გვარი)
A37: ='ინვ. დაქვ. რეზერვ. ოდენობა'!$B$42 -> ანგარიშგებაზე პასუხისმგებელი პირი ________________________________________________________________
A38: ='ინვ. დაქვ. რეზერვ. ოდენობა'!$B$43 -> (სახელი გვარი, ტელეფონის ნომერი, ელ–ფოსტის მისამართი)

Sheet A9
A1: ფორმა N 14.9
A2: A9 მიმართულებით განხორციელებული ინვესტიცია
A4: =რეზერვები!B4 -> კომპანიის დასახელება: ___________________________________
A5: =რეზერვები!B5 -> საანგარიშო თარიღი: ___________________________________
E6: ლარი
A7: A9 | B7: სესხები, რომლებიც უზრუნველყოფილია A1 და A2 მიმართულებით განსაზღვრული ფასიანი ქაღალდებით | C7: ემიტენტის დასახელება, ფასიანი ქაღალდის სახეობა, ემიტენტის რეგისტრაციის ქვეყანა | D7: აქტივის საბალანსო ღირებულება საანგარიშო პერიოდის ბოლოს | E7: ინვესტირებისათვის დასაშვები ოდენობა
A8: 1 | B8: 2 | C8: 3 | D8: 4 | E8: 5
A9: 1 | B9: მსესხებლის დასახელება, რეგისტრაციის ქვეყანა | E9: =IF(D9>'დასაშვები აქტივების სტრუქტურა'!$G$18,'დასაშვები აქტივების სტრუქტურა'!$G$18,D9) -> 0
A10: 2 | B10: მსესხებლის დასახელება, რეგისტრაციის ქვეყანა | E10: =IF(D10>'დასაშვები აქტივების სტრუქტურა'!$G$18,'დასაშვები აქტივების სტრუქტურა'!$G$18,D10) -> 0
A11: 3 | B11: მსესხებლის დასახელება, რეგისტრაციის ქვეყანა | E11: =IF(D11>'დასაშვები აქტივების სტრუქტურა'!$G$18,'დასაშვები აქტივების სტრუქტურა'!$G$18,D11) -> 0
A12: 4 | B12: მსესხებლის დასახელება, რეგისტრაციის ქვეყანა | E12: =IF(D12>'დასაშვები აქტივების სტრუქტურა'!$G$18,'დასაშვები აქტივების სტრუქტურა'!$G$18,D12) -> 0
A13: 5 | B13: მსესხებლის დასახელება, რეგისტრაციის ქვეყანა | E13: =IF(D13>'დასაშვები აქტივების სტრუქტურა'!$G$18,'დასაშვები აქტივების სტრუქტურა'!$G$18,D13) -> 0
A14: 6 | B14: მსესხებლის დასახელება, რეგისტრაციის ქვეყანა | E14: =IF(D14>'დასაშვები აქტივების სტრუქტურა'!$G$18,'დასაშვები აქტივების სტრუქტურა'!$G$18,D14) -> 0
A15: 7 | B15: მსესხებლის დასახელება, რეგისტრაციის ქვეყანა | E15: =IF(D15>'დასაშვები აქტივების სტრუქტურა'!$G$18,'დასაშვები აქტივების სტრუქტურა'!$G$18,D15) -> 0
A16: 8 | B16: მსესხებლის დასახელება, რეგისტრაციის ქვეყანა | E16: =IF(D16>'დასაშვები აქტივების სტრუქტურა'!$G$18,'დასაშვები აქტივების სტრუქტურა'!$G$18,D16) -> 0
A17: 9 | B17: მსესხებლის დასახელება, რეგისტრაციის ქვეყანა | E17: =IF(D17>'დასაშვები აქტივების სტრუქტურა'!$G$18,'დასაშვები აქტივების სტრუქტურა'!$G$18,D17) -> 0
A18: 10 | B18: მსესხებლის დასახელება, რეგისტრაციის ქვეყანა | E18: =IF(D18>'დასაშვები აქტივების სტრუქტურა'!$G$18,'დასაშვები აქტივების სტრუქტურა'!$G$18,D18) -> 0
A19: 11 | B19: მსესხებლის დასახელება, რეგისტრაციის ქვეყანა | E19: =IF(D19>'დასაშვები აქტივების სტრუქტურა'!$G$18,'დასაშვები აქტივების სტრუქტურა'!$G$18,D19) -> 0
A20: 12 | B20: მსესხებლის დასახელება, რეგისტრაციის ქვეყანა | E20: =IF(D20>'დასაშვები აქტივების სტრუქტურა'!$G$18,'დასაშვები აქტივების სტრუქტურა'!$G$18,D20) -> 0
... A28: 20 | B28: მსესხებლის დასახელება, რეგისტრაციის ქვეყანა | E28: =IF(D28>'დასაშვები აქტივების სტრუქტურა'!$G$18,'დასაშვები აქტივების სტრუქტურა'!$G$18,D28) -> 0
B29: სულ | D29: =SUM(D9:D28) -> 0 | E29: =IF(SUM(E9:E28)>'დასაშვები აქტივების სტრუქტურა'!$E$18,'დასაშვები აქტივების სტრუქტურა'!$E$18,SUM(E9:E28)) -> 0
A31: შენიშვნა: ფორმაში მითითებული სესხები არ უნდა იყოს გაცემული მზღვეველთან დაკავშირებულ პირებზე, თუ მზღვეველის მონაწილეობა დაკავშირებული პირების კაპიტალში აღემატება 20%–ს, ან თუ დაკავშირებული პირების მონაწილეობა მზღვეველის კაპიტალში აღემატება 20%–ს.
A33: ='ინვ. დაქვ. რეზერვ. ოდენობა'!$B$38 -> გენერალური დირექტორი (დირექტორი) _____________________________
A34: =რეზერვები!B52 -> (სახელი გვარი)
A37: ='ინვ. დაქვ. რეზერვ. ოდენობა'!$B$42 -> ანგარიშგებაზე პასუხისმგებელი პირი ________________________________________________________________
A38: ='ინვ. დაქვ. რეზერვ. ოდენობა'!$B$43 -> (სახელი გვარი, ტელეფონის ნომერი, ელ–ფოსტის მისამართი)

Sheet A10
A1: ფორმა N 14.10
A2: A10 მიმართულებით განხორციელებული ინვესტიცია
A4: =რეზერვები!B4 -> კომპანიის დასახელება: ___________________________________
A5: =რეზერვები!B5 -> საანგარიშო თარიღი: ___________________________________
E6: ლარი
A7: A10 | B7: საქართველოში, “ეგთო”–ს წევრ ქვეყნებში და/ან განვითარებულ ქვეყნებში რეგისტრირებული უძრავი ქონება | C7: რეგისტრაციის ქვეყანა | D7: აქტივის საბალანსო ღირებულება საანგარიშო პერიოდის ბოლოს | E7: ინვესტირებისათვის დასაშვები ოდენობა
A8: 1 | B8: 2 | C8: 3 | D8: 4 | E8: 5
A9: 1 | B9: უძრავი ქონების დასახელება, ადგილმდებარეობა | E9: =IF(D9>'დასაშვები აქტივების სტრუქტურა'!$G$20,'დასაშვები აქტივების სტრუქტურა'!$G$20,D9) -> 0
A10: 2 | B10: უძრავი ქონების დასახელება, ადგილმდებარეობა | E10: =IF(D10>'დასაშვები აქტივების სტრუქტურა'!$G$20,'დასაშვები აქტივების სტრუქტურა'!$G$20,D10) -> 0
A11: 3 | B11: უძრავი ქონების დასახელება, ადგილმდებარეობა | E11: =IF(D11>'დასაშვები აქტივების სტრუქტურა'!$G$20,'დასაშვები აქტივების სტრუქტურა'!$G$20,D11) -> 0
A12: 4 | B12: უძრავი ქონების დასახელება, ადგილმდებარეობა | E12: =IF(D12>'დასაშვები აქტივების სტრუქტურა'!$G$20,'დასაშვები აქტივების სტრუქტურა'!$G$20,D12) -> 0
A13: 5 | B13: უძრავი ქონების დასახელება, ადგილმდებარეობა | E13: =IF(D13>'დასაშვები აქტივების სტრუქტურა'!$G$20,'დასაშვები აქტივების სტრუქტურა'!$G$20,D13) -> 0
A14: 6 | B14: უძრავი ქონების დასახელება, ადგილმდებარეობა | E14: =IF(D14>'დასაშვები აქტივების სტრუქტურა'!$G$20,'დასაშვები აქტივების სტრუქტურა'!$G$20,D14) -> 0
A15: 7 | B15: უძრავი ქონების დასახელება, ადგილმდებარეობა | E15: =IF(D15>'დასაშვები აქტივების სტრუქტურა'!$G$20,'დასაშვები აქტივების სტრუქტურა'!$G$20,D15) -> 0
A16: 8 | B16: უძრავი ქონების დასახელება, ადგილმდებარეობა | E16: =IF(D16>'დასაშვები აქტივების სტრუქტურა'!$G$20,'დასაშვები აქტივების სტრუქტურა'!$G$20,D16) -> 0
A17: 9 | B17: უძრავი ქონების დასახელება, ადგილმდებარეობა | E17: =IF(D17>'დასაშვები აქტივების სტრუქტურა'!$G$20,'დასაშვები აქტივების სტრუქტურა'!$G$20,D17) -> 0
A18: 10 | B18: უძრავი ქონების დასახელება, ადგილმდებარეობა | E18: =IF(D18>'დასაშვები აქტივების სტრუქტურა'!$G$20,'დასაშვები აქტივების სტრუქტურა'!$G$20,D18) -> 0
A19: 11 | B19: უძრავი ქონების დასახელება, ადგილმდებარეობა | E19: =IF(D19>'დასაშვები აქტივების სტრუქტურა'!$G$20,'დასაშვები აქტივების სტრუქტურა'!$G$20,D19) -> 0
A20: 12 | B20: უძრავი ქონების დასახელება, ადგილმდებარეობა | E20: =IF(D20>'დასაშვები აქტივების სტრუქტურა'!$G$20,'დასაშვები აქტივების სტრუქტურა'!$G$20,D20) -> 0
... A28: 20 | B28: უძრავი ქონების დასახელება, ადგილმდებარეობა | E28: =IF(D28>'დასაშვები აქტივების სტრუქტურა'!$G$20,'დასაშვები აქტივების სტრუქტურა'!$G$20,D28) -> 0
B29: სულ | D29: =SUM(D9:D28) -> 0 | E29: =IF(SUM(E9:E28)>'დასაშვები აქტივების სტრუქტურა'!$E$20,'დასაშვები აქტივების სტრუქტურა'!$E$20,SUM(E9:E28)) -> 0
A31: შენიშვნა: ფორმაში მითითებული აქტივების მიმართ გამოყენებული არ უნდა იყოს საქართველოს კანონმდებლობით გათვალისწინებული უზრუნველყოფის საშუალებები (ყადაღა, იპოთეკა, გირავნობა და სხვა).
A33: ='ინვ. დაქვ. რეზერვ. ოდენობა'!$B$38 -> გენერალური დირექტორი (დირექტორი) _____________________________
A34: =რეზერვები!B52 -> (სახელი გვარი)
A37: ='ინვ. დაქვ. რეზერვ. ოდენობა'!$B$42 -> ანგარიშგებაზე პასუხისმგებელი პირი ________________________________________________________________
A38: ='ინვ. დაქვ. რეზერვ. ოდენობა'!$B$43 -> (სახელი გვარი, ტელეფონის ნომერი, ელ–ფოსტის მისამართი)

Sheet A11
A1: ფორმა N 14.11
A2: A11 მიმართულებით განხორციელებული ინვესტიცია
A4: =რეზერვები!B4 -> კომპანიის დასახელება: ___________________________________
A5: =რეზერვები!B5 -> საანგარიშო თარიღი: ___________________________________
E6: ლარი
A7: A11 | B7: დეპოზიტები საბანკო დაწესებულებებში | C7: ბანკის რეგისტრაციის ქვეყანა | D7: აქტივის ოდენობა საანგარიშო პერიოდის ბოლოს | E7: ინვესტირებისათვის დასაშვები ოდენობა
A8: 1 | B8: 2 | C8: 3 | D8: 4 | E8: 5
A9: 1 | B9: საბანკო დაწესებულების დასახელება | E9: =IF(D9>'დასაშვები აქტივების სტრუქტურა'!$G$21,'დასაშვები აქტივების სტრუქტურა'!$G$21,D9) -> 0
A10: 2 | B10: საბანკო დაწესებულების დასახელება | E10: =IF(D10>'დასაშვები აქტივების სტრუქტურა'!$G$21,'დასაშვები აქტივების სტრუქტურა'!$G$21,D10) -> 0
A11: 3 | B11: საბანკო დაწესებულების დასახელება | E11: =IF(D11>'დასაშვები აქტივების სტრუქტურა'!$G$21,'დასაშვები აქტივების სტრუქტურა'!$G$21,D11) -> 0
A12: 4 | B12: საბანკო დაწესებულების დასახელება | E12: =IF(D12>'დასაშვები აქტივების სტრუქტურა'!$G$21,'დასაშვები აქტივების სტრუქტურა'!$G$21,D12) -> 0
A13: 5 | B13: საბანკო დაწესებულების დასახელება | E13: =IF(D13>'დასაშვები აქტივების სტრუქტურა'!$G$21,'დასაშვები აქტივების სტრუქტურა'!$G$21,D13) -> 0
A14: 6 | B14: საბანკო დაწესებულების დასახელება | E14: =IF(D14>'დასაშვები აქტივების სტრუქტურა'!$G$21,'დასაშვები აქტივების სტრუქტურა'!$G$21,D14) -> 0
A15: 7 | B15: საბანკო დაწესებულების დასახელება | E15: =IF(D15>'დასაშვები აქტივების სტრუქტურა'!$G$21,'დასაშვები აქტივების სტრუქტურა'!$G$21,D15) -> 0
A16: 8 | B16: საბანკო დაწესებულების დასახელება | E16: =IF(D16>'დასაშვები აქტივების სტრუქტურა'!$G$21,'დასაშვები აქტივების სტრუქტურა'!$G$21,D16) -> 0
A17: 9 | B17: საბანკო დაწესებულების დასახელება | E17: =IF(D17>'დასაშვები აქტივების სტრუქტურა'!$G$21,'დასაშვები აქტივების სტრუქტურა'!$G$21,D17) -> 0
A18: 10 | B18: საბანკო დაწესებულების დასახელება | E18: =IF(D18>'დასაშვები აქტივების სტრუქტურა'!$G$21,'დასაშვები აქტივების სტრუქტურა'!$G$21,D18) -> 0
A19: 11 | B19: საბანკო დაწესებულების დასახელება | E19: =IF(D19>'დასაშვები აქტივების სტრუქტურა'!$G$21,'დასაშვები აქტივების სტრუქტურა'!$G$21,D19) -> 0
A20: 12 | B20: საბანკო დაწესებულების დასახელება | E20: =IF(D20>'დასაშვები აქტივების სტრუქტურა'!$G$21,'დასაშვები აქტივების სტრუქტურა'!$G$21,D20) -> 0
... A28: 20 | B28: საბანკო დაწესებულების დასახელება | E28: =IF(D28>'დასაშვები აქტივების სტრუქტურა'!$G$21,'დასაშვები აქტივების სტრუქტურა'!$G$21,D28) -> 0
B29: სულ | D29: =SUM(D9:D28) -> 0 | E29: =IF(SUM(E9:E28)>'დასაშვები აქტივების სტრუქტურა'!$E$21,'დასაშვები აქტივების სტრუქტურა'!$E$21,SUM(E9:E28)) -> 0
A31: შენიშვნა: ფორმაში მითითებული აქტივების მიმართ გამოყენებული არ უნდა იყოს საქართველოს კანონმდებლობით გათვალისწინებული უზრუნველყოფის საშუალებები (ყადაღა, იპოთეკა, გირავნობა და სხვა).
A33: ='ინვ. დაქვ. რეზერვ. ოდენობა'!$B$38 -> გენერალური დირექტორი (დირექტორი) _____________________________
A34: =რეზერვები!B52 -> (სახელი გვარი)
A37: ='ინვ. დაქვ. რეზერვ. ოდენობა'!$B$42 -> ანგარიშგებაზე პასუხისმგებელი პირი ________________________________________________________________
B38: ='ინვ. დაქვ. რეზერვ. ოდენობა'!$B$43 -> (სახელი გვარი, ტელეფონის ნომერი, ელ–ფოსტის მისამართი)

Sheet A12
A1: ფორმა N 14.12
A2: A12 მიმართულებით განხორციელებული ინვესტიცია
A4: =რეზერვები!B4 -> კომპანიის დასახელება: ___________________________________
A5: =რეზერვები!B5 -> საანგარიშო თარიღი: ___________________________________
E6: ლარი
A7: A12 | B7: ფული სალაროში და საბანკო დაწესებულებებში გახსნილ მიმდინარე ანგარიშებზე | C7: რეგისტრაციის ქვეყანა | D7: აქტივის ოდენობა საანგარიშო პერიოდის ბოლოს | E7: ინვესტირებისათვის დასაშვები ოდენობა
A8: 1 | B8: 2 | C8: 3 | D8: 4 | E8: 5
A9: 1 | B9: ფული სალაროში | E9: =IF(D9>'დასაშვები აქტივების სტრუქტურა'!$G$22,'დასაშვები აქტივების სტრუქტურა'!$G$22,D9) -> 0
A10: 2 | B10: საბანკო დაწესებულების დასახელება | E10: =IF(D10>'დასაშვები აქტივების სტრუქტურა'!$G$23,'დასაშვები აქტივების სტრუქტურა'!$G$23,D10) -> 0
A11: 3 | B11: საბანკო დაწესებულების დასახელება | E11: =IF(D11>'დასაშვები აქტივების სტრუქტურა'!$G$23,'დასაშვები აქტივების სტრუქტურა'!$G$23,D11) -> 0
A12: 4 | B12: საბანკო დაწესებულების დასახელება | E12: =IF(D12>'დასაშვები აქტივების სტრუქტურა'!$G$23,'დასაშვები აქტივების სტრუქტურა'!$G$23,D12) -> 0
A13: 5 | B13: საბანკო დაწესებულების დასახელება | E13: =IF(D13>'დასაშვები აქტივების სტრუქტურა'!$G$23,'დასაშვები აქტივების სტრუქტურა'!$G$23,D13) -> 0
A14: 6 | B14: საბანკო დაწესებულების დასახელება | E14: =IF(D14>'დასაშვები აქტივების სტრუქტურა'!$G$23,'დასაშვები აქტივების სტრუქტურა'!$G$23,D14) -> 0
A15: 7 | B15: საბანკო დაწესებულების დასახელება | E15: =IF(D15>'დასაშვები აქტივების სტრუქტურა'!$G$23,'დასაშვები აქტივების სტრუქტურა'!$G$23,D15) -> 0
A16: 8 | B16: საბანკო დაწესებულების დასახელება | E16: =IF(D16>'დასაშვები აქტივების სტრუქტურა'!$G$23,'დასაშვები აქტივების სტრუქტურა'!$G$23,D16) -> 0
A17: 9 | B17: საბანკო დაწესებულების დასახელება | E17: =IF(D17>'დასაშვები აქტივების სტრუქტურა'!$G$23,'დასაშვები აქტივების სტრუქტურა'!$G$23,D17) -> 0
A18: 10 | B18: საბანკო დაწესებულების დასახელება | E18: =IF(D18>'დასაშვები აქტივების სტრუქტურა'!$G$23,'დასაშვები აქტივების სტრუქტურა'!$G$23,D18) -> 0
A19: 11 | B19: საბანკო დაწესებულების დასახელება | E19: =IF(D19>'დასაშვები აქტივების სტრუქტურა'!$G$23,'დასაშვები აქტივების სტრუქტურა'!$G$23,D19) -> 0
A20: 12 | B20: საბანკო დაწესებულების დასახელება | E20: =IF(D20>'დასაშვები აქტივების სტრუქტურა'!$G$23,'დასაშვები აქტივების სტრუქტურა'!$G$23,D20) -> 0
A21: 13 | B21: საბანკო დაწესებულების დასახელება | E21: =IF(D21>'დასაშვები აქტივების სტრუქტურა'!$G$23,'დასაშვები აქტივების სტრუქტურა'!$G$23,D21) -> 0
... A28: 20 | B28: საბანკო დაწესებულების დასახელება | E28: =IF(D28>'დასაშვები აქტივების სტრუქტურა'!$G$23,'დასაშვები აქტივების სტრუქტურა'!$G$23,D28) -> 0
A29: ='დასაშვები აქტივების სტრუქტურა'!I22 -> 0 | B29: სულ | D29: =SUM(D9:D28) -> 0 | E29: =IF(SUM(E9:E28)>'დასაშვები აქტივების სტრუქტურა'!$E$23,'დასაშვები აქტივების სტრუქტურა'!$E$23,SUM(E9:E28)) -> 0
A31: შენიშვნა: ფორმაში მითითებული აქტივების მიმართ გამოყენებული არ უნდა იყოს საქართველოს კანონმდებლობით გათვალისწინებული უზრუნველყოფის საშუალებები (ყადაღა, იპოთეკა, გირავნობა და სხვა);
A32: შენიშვნა: ფორმაში მითითებული აქტივების ჯამური ოდენობა არ უნდა იყოს ინვესტირებისათვის დაქვემდებარებული სადაზღვევო რეზერვების 10%–ზე ნაკლები.
A34: ='ინვ. დაქვ. რეზერვ. ოდენობა'!$B$38 -> გენერალური დირექტორი (დირექტორი) _____________________________
A35: =რეზერვები!B52 -> (სახელი გვარი)
A38: ='ინვ. დაქვ. რეზერვ. ოდენობა'!$B$42 -> ანგარიშგებაზე პასუხისმგებელი პირი ________________________________________________________________
B39: ='ინვ. დაქვ. რეზერვ. ოდენობა'!$B$43 -> (სახელი გვარი, ტელეფონის ნომერი, ელ–ფოსტის მისამართი)

Sheet ინვესტირება
B1: ფორმა 14
B2: სადაზღვევო რეზერვების დასაფარად დასაშვები აქტივების სტრუქტურა
B4: =რეზერვები!B4 -> კომპანიის დასახელება: ___________________________________
B5: =რეზერვები!B5 -> საანგარიშო თარიღი: ___________________________________
E6: ლარი
B7: აქტივის კოდი | C7: აქტივის დასახელება | D7: ინვესტირებისათვის დაშვებული თანხის ოდენობა (თითოეული მიმართულების შეზღუდვების მიხედვით) | E7: ინვესტირებისათვის დაშვებული თანხის ოდენობა (ჯგუფური შეზღუდვების მიხედვით)
B8: ='A1'!A7 -> A1 | C8: ='A1'!B7 -> საქართველოს, "ეგთო"–ს წევრი ქვეყნებისა და/ან განვითარებული ქვეყნების ცენტრალური მთავრობების მიერ გამოშვებული სასესხო ფასიანი ქაღალდები | D8: ='A1'!E29 -> 0 | E8: =IF((D8+D9)>'დასაშვები აქტივების სტრუქტურა'!E10,'დასაშვები აქტივების სტრუქტურა'!E10,D8+D9) -> 0
B9: ='A2'!A7 -> A2 | C9: ='A2'!B7 -> "ეგთო"–ს წევრი ქვეყნებისა და/ან განვითარებული ქვეყნების ადგილობრივი თვითმმართველობის ერთეულების შესაბამისი ორგანოების მიერ გამოშვებული სასესხო ფასიანი ქაღალდები | D9: ='A2'!E29 -> 0
B10: ='A3'!A7 -> A3 | C10: ='A3'!B7 -> სასესხო ფასიანი ქაღალდები (ობლიგაციები) და პრივილეგირებული აქციები, რომელთა მიმოქცევა ხორციელდება საქართველოს, "ეგთო"–ს წევრი ქვეყნების და/ან განვითარებული ქვეყნების ფასიანი ქაღალდების ორგანიზებულ ბაზარზე | D10: ='A3'!F29 -> 0 | E10: =IF((D10+D11+D12+D13)>'დასაშვები აქტივების სტრუქტურა'!E15,'დასაშვები აქტივების სტრუქტურა'!E15,D10+D11+D12+D13) -> 0
B11: ='A4'!A7 -> A4 | C11: ='A4'!B7 -> საქართველოში, “ეგთო”–ს წევრ ქვეყნებში და/ან განვითარებულ ქვეყნებში რეგისტრირებული იურიდიული პირების მიერ გამოშვებული სასესხო ფასიანი ქაღალდები (ობლიგაციები) და პრივილეგირებული აქციები, რომელთა მიმოქცევა ხორციელდება ფასიანი ქაღალდების ორგანიზებული ბაზრის გარეთ | D11: ='A4'!E29 -> 0
B12: ='A5'!A7 -> A5 | C12: ='A5'!B7 -> წილობრივი ფასიანი ქაღალდები (გარდა პრივილეგირებული აქციებისა), რომელთა მიმოქცევა ხორციელდება საქართველოს, “ეგთო”–ს წევრი ქვეყნების და/ან განვითარებული ქვეყნების ფასიანი ქაღალდების ორგანიზებულ ბაზარზე | D12: ='A5'!F29 -> 0
B13: ='A6'!A7 -> A6 | C13: ='A6'!B7 -> საქართველოში, “ეგთო”–ს წევრ ქვეყნებში და/ან განვითარებულ ქვეყნებში რეგისტრირებული იურიდიული პირების მიერ გამოშვებული წილობრივი ფასიანი ქაღალდები (გარდა პრივილეგირებული აქციებისა), რომელთა მიმოქცევა ხორციელდება ფასიანი ქაღალდების ორგანიზებული ბაზრის გარეთ | D13: ='A6'!E29 -> 0
B14: ='A7'!A7 -> A7 | C14: ='A7'!B7 -> საქართველოში, “ეგთო”–ს წევრ ქვეყნებში და/ან განვითარებულ ქვეყნებში რეგისტრირებული ქონების უზრუნველყოფით გაცემული იპოთეკური სესხები | D14: ='A7'!E29 -> 0 | E14: =IF((D14+D15+D16)>'დასაშვები აქტივების სტრუქტურა'!E19,'დასაშვები აქტივების სტრუქტურა'!E19,D14+D15+D16) -> 0
B15: ='A8'!A7 -> A8 | C15: ='A8'!B7 -> საქართველოს, "ეგთო"–ს წევრ ქვეყნებისა და/ან განვითარებული ქვეყნების შესაბამისი უფლებამოსილების მქონე ორგანოს მიერ ლიცენზირებული საბანკო დაწესებულებებისათვის გაცემული სესხები | D15: ='A8'!E29 -> 0
B16: ='A9'!A7 -> A9 | C16: ='A9'!B7 -> სესხები, რომლებიც უზრუნველყოფილია A1 და A2 მიმართულებით განსაზღვრული ფასიანი ქაღალდებით | D16: ='A9'!E29 -> 0
B17: ='A10'!A7 -> A10 | C17: ='A10'!B7 -> საქართველოში, “ეგთო”–ს წევრ ქვეყნებში და/ან განვითარებულ ქვეყნებში რეგისტრირებული უძრავი ქონება | D17: ='A10'!E29 -> 0 | E17: =IF(D17>'დასაშვები აქტივების სტრუქტურა'!E20,'დასაშვები აქტივების სტრუქტურა'!E20,D17) -> 0
B18: ='A11'!A7 -> A11 | C18: ='A11'!B7 -> დეპოზიტები საბანკო დაწესებულებებში | D18: ='A11'!E29 -> 0 | E18: =IF(D18>'დასაშვები აქტივების სტრუქტურა'!E21,'დასაშვები აქტივების სტრუქტურა'!E21,D18) -> 0
B19: ='A12'!A7 -> A12 | C19: ='A12'!B7 -> ფული სალაროში და საბანკო დაწესებულებებში გახსნილ მიმდინარე ანგარიშებზე | D19: ='A12'!E29 -> 0 | E19: =IF(D19>'დასაშვები აქტივების სტრუქტურა'!E23,'დასაშვები აქტივების სტრუქტურა'!E23,D19) -> 0
B20: ='ინვ. დაქვ. რეზერვ. ოდენობა'!D35 -> 0 | C20: ინვესტირებისათვის დაშვებული აქტივების ოდენობა | D20: =SUM(D8:D19) -> 0 | E20: =E8+E10+E14+E17+E18+E19 -> 0
B22: A13 | C22: სადაზღვევო მოთხოვნები (ფინანსური ანგარიშგების ფორმა N 1-4, სულ სადაზღვევო მოთხოვნები, წმინდა 00100-სტრიქონში ასახულ სადაზღვევო მოთხოვნებში) | E22: ='ინვ. დაქვ. რეზერვ. ოდენობა'!D10 -> 0
B23: A14 | C23: გადამზღვევლის წილი სადაზღვევო რეზერვებში | E23: ='ინვ. დაქვ. რეზერვ. ოდენობა'!D9+'ინვ. დაქვ. რეზერვ. ოდენობა'!D17+'ინვ. დაქვ. რეზერვ. ოდენობა'!D33 -> 0
B24: A15 | C24: ანაზღაურებულ ზარალებთან დაკავშირებული მოთხოვნები გადაზღვევიდან (იმ მოთხოვნების გამოკლებით, სადაც მზღვეველის მიერ ზარალის სრული ოდენობის ანაზღაურების თარიღიდან 1 წელზე მეტი დროის პერიოდია გასული) | E24: ='ინვ. დაქვ. რეზერვ. ოდენობა'!D18-'ინვ. დაქვ. რეზერვ. ოდენობა'!D19 -> 0
B25: ='ინვ. დაქვ. რეზერვ. ოდენობა'!D8+'ინვ. დაქვ. რეზერვ. ოდენობა'!D16+'ინვ. დაქვ. რეზერვ. ოდენობა'!D24+'ინვ. დაქვ. რეზერვ. ოდენობა'!D29+'ინვ. დაქვ. რეზერვ. ოდენობა'!D32 -> 0 | C25: სადაზღვევო რეზერვების დასაფარად დაშვებული აქტივები სულ | E25: =E20+E22+E23+E24 -> 0
B28: ='ინვ. დაქვ. რეზერვ. ოდენობა'!$B$38 -> გენერალური დირექტორი (დირექტორი) _____________________________
B29: =რეზერვები!B52 -> (სახელი გვარი)
B32: ='ინვ. დაქვ. რეზერვ. ოდენობა'!$B$42 -> ანგარიშგებაზე პასუხისმგებელი პირი ________________________________________________________________
B33: ='ინვ. დაქვ. რეზერვ. ოდენობა'!$B$43 -> (სახელი გვარი, ტელეფონის ნომერი, ელ–ფოსტის მისამართი)
